Workbook
Name _MailAutoSig: '06_發行案件'!#REF!
Name _MailAutoSig: '07_董事會決議'!#REF!
Name AUpdate: 1
Name BUpdate: 1
Name GUpdate: 0
Name NoUpdate: ""
Name Sheet1.漲跌幅: "round(((cast([6^6] as real)/cast([0^0] as real))-1),2)"
Name Sheet1.漲跌幅old: "I6,C6"
Name Sheet1.漲跌幅where: "(cast([0^6] as real)<>0)"
Name TUpdate: 1
Name XX_TEJ1: #REF!
Name XX_TEJ2: #REF!
Name 股票名稱: #REF!
Name 泰金二KY: #REF!
Name 富貴50: #REF!
Name 資料庫.股本: "round(cast([39^0] as real)/10,1)"
Name 資料庫.股本.億: "round(cast([39^0] as real)/100,1)"
Name 資料庫.股本.億old: "AP6"
Name 資料庫.股本.億where: "(100<>0)"
Name 資料庫.股本old: "AP6"
Name 資料庫.股本where: "(10<>0)"

Sheet 00_CB代號名稱過濾及掛牌高低_20251031
A1: 股票代號 | B1: 代號 | C1: 名稱 | D1: 掛牌最高 | E1: 掛牌最低 | F1: 資金用途 | G1: 掛牌日期 | H1: 資金用途分類
A2: 1101 | B2: 11011 | C2: 台泥一永 | D2: =IFERROR(VLOOKUP(B2,[1]最高價!$A:$C,3,FALSE),"") -> 108.1 | E2: =IFERROR(VLOOKUP(B2,[1]最低價!$A:$C,3,FALSE),"") -> 94.4 | F2: 轉投資海外子公司 TCC Dutch131.6億，償還銀行借款61.54億，共計193.15億 | G2: =VLOOKUP(B2,'[2]01_ALLCB基本資料'!C:U,16,FALSE) -> 45636 | H2: 償還銀行借款
A3: 1210 | B3: 12101 | C3: 大成一 | D3: =IFERROR(VLOOKUP(B3,[1]最高價!$A:$C,3,FALSE),"") -> 127 | E3: =IFERROR(VLOOKUP(B3,[1]最低價!$A:$C,3,FALSE),"") -> 72.5 | G3: =VLOOKUP(B3,'[2]01_ALLCB基本資料'!C:U,16,FALSE) -> 39336
A4: 1216 | B4: 12161 | C4: 統一一 | D4: =IFERROR(VLOOKUP(B4,[1]最高價!$A:$C,3,FALSE),"") -> 106.75 | E4: =IFERROR(VLOOKUP(B4,[1]最低價!$A:$C,3,FALSE),"") -> 91.2 | G4: =VLOOKUP(B4,'[2]01_ALLCB基本資料'!C:U,16,FALSE) -> 39370
A5: 1217 | B5: 12171 | C5: 愛之味一 | D5: =IFERROR(VLOOKUP(B5,[1]最高價!$A:$C,3,FALSE),"") -> 123 | E5: =IFERROR(VLOOKUP(B5,[1]最低價!$A:$C,3,FALSE),"") -> 100 | G5: =VLOOKUP(B5,'[2]01_ALLCB基本資料'!C:U,16,FALSE) -> 40664
A6: 1217 | B6: 12172 | C6: 愛之味二 | D6: =IFERROR(VLOOKUP(B6,[1]最高價!$A:$C,3,FALSE),"") -> 112 | E6: =IFERROR(VLOOKUP(B6,[1]最低價!$A:$C,3,FALSE),"") -> 89 | G6: =VLOOKUP(B6,'[2]01_ALLCB基本資料'!C:U,16,FALSE) -> 40675
A7: 1217 | B7: 12173 | C7: 愛之味三 | D7: =IFERROR(VLOOKUP(B7,[1]最高價!$A:$C,3,FALSE),"") -> 105 | E7: =IFERROR(VLOOKUP(B7,[1]最低價!$A:$C,3,FALSE),"") -> 99.6 | F7: 償還銀行借款6億，充實營運資金3億，購置設備1億 | G7: =VLOOKUP(B7,'[2]01_ALLCB基本資料'!C:U,16,FALSE) -> 41340 | H7: 償還+充實
A8: 1218 | B8: 12181 | C8: 泰山一 | D8: =IFERROR(VLOOKUP(B8,[1]最高價!$A:$C,3,FALSE),"") -> 109.9 | E8: =IFERROR(VLOOKUP(B8,[1]最低價!$A:$C,3,FALSE),"") -> 99 | F8: 償還銀行借款5億 | G8: =VLOOKUP(B8,'[2]01_ALLCB基本資料'!C:U,16,FALSE) -> 41417 | H8: 償還銀行借款
A9: 1225 | B9: 12251 | C9: 福脂一 | D9: =IFERROR(VLOOKUP(B9,[1]最高價!$A:$C,3,FALSE),"") -> 233 | E9: =IFERROR(VLOOKUP(B9,[1]最低價!$A:$C,3,FALSE),"") -> 101 | G9: =VLOOKUP(B9,'[2]01_ALLCB基本資料'!C:U,16,FALSE) -> 40158
A10: 1258 | B10: 12581 | C10: 其祥一KY | D10: =IFERROR(VLOOKUP(B10,[1]最高價!$A:$C,3,FALSE),"") -> 124.25 | E10: =IFERROR(VLOOKUP(B10,[1]最低價!$A:$C,3,FALSE),"") -> 99.1 | G10: =VLOOKUP(B10,'[2]01_ALLCB基本資料'!C:U,16,FALSE) -> 42262
A11: 1258 | B11: 12582 | C11: 其祥二KY | D11: =IFERROR(VLOOKUP(B11,[1]最高價!$A:$C,3,FALSE),"") -> 101.3 | E11: =IFERROR(VLOOKUP(B11,[1]最低價!$A:$C,3,FALSE),"") -> 76.2 | G11: =VLOOKUP(B11,'[2]01_ALLCB基本資料'!C:U,16,FALSE) -> 43353
A12: 1312 | B12: 13121 | C12: 國喬一 | D12: =IFERROR(VLOOKUP(B12,[1]最高價!$A:$C,3,FALSE),"") -> 171 | E12: =IFERROR(VLOOKUP(B12,[1]最低價!$A:$C,3,FALSE),"") -> 90 | G12: =VLOOKUP(B12,'[2]01_ALLCB基本資料'!C:U,16,FALSE)
A13: 1316 | B13: 13161 | C13: 上曜一 | D13: =IFERROR(VLOOKUP(B13,[1]最高價!$A:$C,3,FALSE),"") -> 122 | E13: =IFERROR(VLOOKUP(B13,[1]最低價!$A:$C,3,FALSE),"") -> 99.65 | F13: 償還銀行借款0.8億，購置機器設備1億，充實營運資金1.2億 | G13: =VLOOKUP(B13,'[2]01_ALLCB基本資料'!C:U,16,FALSE) -> 40757 | H13: 償還+充實
A14: 1316 | B14: 13162 | C14: 上曜二 | D14: =IFERROR(VLOOKUP(B14,[1]最高價!$A:$C,3,FALSE),"") -> 177 | E14: =IFERROR(VLOOKUP(B14,[1]最低價!$A:$C,3,FALSE),"") -> 104 | F14: 現金增資3億，上曜二募得2億，充實營運資金5億 | G14: =VLOOKUP(B14,'[2]01_ALLCB基本資料'!C:U,16,FALSE) -> 41996 | H14: 充實營運資金
A15: 1316 | B15: 13163 | C15: 上曜三 | D15: =IFERROR(VLOOKUP(B15,[1]最高價!$A:$C,3,FALSE),"") -> 117.95 | E15: =IFERROR(VLOOKUP(B15,[1]最低價!$A:$C,3,FALSE),"") -> 99.6 | F15: 充實營運資金13億 | G15: =VLOOKUP(B15,'[2]01_ALLCB基本資料'!C:U,16,FALSE) -> 43411 | H15: 充實營運資金
A16: 1316 | B16: 13164 | C16: 上曜四 | D16: =IFERROR(VLOOKUP(B16,[1]最高價!$A:$C,3,FALSE),"") -> 189 | E16: =IFERROR(VLOOKUP(B16,[1]最低價!$A:$C,3,FALSE),"") -> 101.5 | F16: 充實營運資金7.04億，償還銀行借款1億，與上曜五同時發行 | G16: =VLOOKUP(B16,'[2]01_ALLCB基本資料'!C:U,16,FALSE) -> 44225 | H16: 償還+充實
A17: 1316 | B17: 13165 | C17: 上曜五 | D17: =IFERROR(VLOOKUP(B17,[1]最高價!$A:$C,3,FALSE),"") -> 232 | E17: =IFERROR(VLOOKUP(B17,[1]最低價!$A:$C,3,FALSE),"") -> 99.6 | F17: 充實營運資金7.04億，償還銀行借款1億，與上曜四同時發行 | G17: =VLOOKUP(B17,'[2]01_ALLCB基本資料'!C:U,16,FALSE) -> 44228 | H17: 償還+充實
A18: 1316 | B18: 13166 | C18: 上曜六 | D18: =IFERROR(VLOOKUP(B18,[1]最高價!$A:$C,3,FALSE),"") -> 125.5 | E18: =IFERROR(VLOOKUP(B18,[1]最低價!$A:$C,3,FALSE),"") -> 102.8 | F18: 充實營運資金共計11.8億，CB6發行4000張，現增65000張，認購價12元 | G18: =VLOOKUP(B18,'[2]01_ALLCB基本資料'!C:U,16,FALSE) -> 45653 | H18: 充實營運資金
A19: 1319 | B19: 13191 | C19: 東陽一 | D19: =IFERROR(VLOOKUP(B19,[1]最高價!$A:$C,3,FALSE),"") -> 115 | E19: =IFERROR(VLOOKUP(B19,[1]最低價!$A:$C,3,FALSE),"") -> 95.4 | G19: =VLOOKUP(B19,'[2]01_ALLCB基本資料'!C:U,16,FALSE) -> 40536
A20: 1336 | B20: 13361 | C20: 台翰一 | D20: =IFERROR(VLOOKUP(B20,[1]最高價!$A:$C,3,FALSE),"") -> 116 | E20: =IFERROR(VLOOKUP(B20,[1]最低價!$A:$C,3,FALSE),"") -> 101.1 | F20: 償還銀行借款及商業本票2.74億，充實營運資金0.77億 | G20: =VLOOKUP(B20,'[2]01_ALLCB基本資料'!C:U,16,FALSE) -> 41892 | H20: 償還+充實
A21: 1337 | B21: 13371 | C21: 再生一 | D21: =IFERROR(VLOOKUP(B21,[1]最高價!$A:$C,3,FALSE),"") -> 120.5 | E21: =IFERROR(VLOOKUP(B21,[1]最低價!$A:$C,3,FALSE),"") -> 82.95 | F21: 現金增資13.69億，再生一KY募得6億，擴廠18.83億，購買機器設備11.63億 | G21: =VLOOKUP(B21,'[2]01_ALLCB基本資料'!C:U,16,FALSE) -> 41193 | H21: 資本支出
A22: 1338 | B22: 13381 | C22: 廣華一KY | D22: =IFERROR(VLOOKUP(B22,[1]最高價!$A:$C,3,FALSE),"") -> 117 | E22: =IFERROR(VLOOKUP(B22,[1]最低價!$A:$C,3,FALSE),"") -> 97.1 | F22: 償還銀行借款4.95億及充實營運資金1.05億，共計6億元。 | G22: =VLOOKUP(B22,'[2]01_ALLCB基本資料'!C:U,16,FALSE) -> 44215 | H22: 償還+充實
A23: 1338 | B23: 13382 | C23: 廣華二KY | D23: =IFERROR(VLOOKUP(B23,[1]最高價!$A:$C,3,FALSE),"") -> 115.5 | E23: =IFERROR(VLOOKUP(B23,[1]最低價!$A:$C,3,FALSE),"") -> 93.05 | F23: 償還第一次轉換公司債6.09億 | G23: =VLOOKUP(B23,'[2]01_ALLCB基本資料'!C:U,16,FALSE) -> 45261 | H23: 借新還舊
A24: 1341 | B24: 13411 | C24: 富林一KY | D24: =IFERROR(VLOOKUP(B24,[1]最高價!$A:$C,3,FALSE),"") -> 116.9 | E24: =IFERROR(VLOOKUP(B24,[1]最低價!$A:$C,3,FALSE),"") -> 100.8 | F24: 現金增資0.5億，1000張/50元，富林一募得1.72億，充實營運資金2.22億 | G24: =VLOOKUP(B24,'[2]01_ALLCB基本資料'!C:U,16,FALSE) -> 44329 | H24: 充實營運資金
A25: 1342 | B25: 13421 | C25: 八貫一 | D25: =IFERROR(VLOOKUP(B25,[1]最高價!$A:$C,3,FALSE),"") -> 243 | E25: =IFERROR(VLOOKUP(B25,[1]最低價!$A:$C,3,FALSE),"") -> 106.5 | F25: 充實營運資金2.25億 | G25: =VLOOKUP(B25,'[2]01_ALLCB基本資料'!C:U,16,FALSE) -> 44714 | H25: 充實營運資金
A26: 1409 | B26: 14093 | C26: 新纖三 | D26: =IFERROR(VLOOKUP(B26,[1]最高價!$A:$C,3,FALSE),"") -> 180 | E26: =IFERROR(VLOOKUP(B26,[1]最低價!$A:$C,3,FALSE),"") -> 77 | G26: =VLOOKUP(B26,'[2]01_ALLCB基本資料'!C:U,16,FALSE) -> 39189
A27: 1432 | B27: 14321 | C27: 大魯閣一 | D27: =IFERROR(VLOOKUP(B27,[1]最高價!$A:$C,3,FALSE),"") -> 119 | E27: =IFERROR(VLOOKUP(B27,[1]最低價!$A:$C,3,FALSE),"") -> 100.5 | F27: 轉投資大魯閣開發股分有限公司5億，與大魯閣二同時發行 | G27: =VLOOKUP(B27,'[2]01_ALLCB基本資料'!C:U,16,FALSE) -> 42047 | H27: 轉投資
A28: 1432 | B28: 14322 | C28: 大魯閣二 | D28: =IFERROR(VLOOKUP(B28,[1]最高價!$A:$C,3,FALSE),"") -> 119.1 | E28: =IFERROR(VLOOKUP(B28,[1]最低價!$A:$C,3,FALSE),"") -> 92.3 | F28: 轉投資大魯閣開發股分有限公司5億，與大魯閣一同時發行 | G28: =VLOOKUP(B28,'[2]01_ALLCB基本資料'!C:U,16,FALSE) -> 42048 | H28: 轉投資
A29: 1436 | B29: 14361 | C29: 華友聯一 | D29: =IFERROR(VLOOKUP(B29,[1]最高價!$A:$C,3,FALSE),"") -> 695 | E29: =IFERROR(VLOOKUP(B29,[1]最低價!$A:$C,3,FALSE),"") -> 106 | F29: 償還銀行借款3.78億 | G29: =VLOOKUP(B29,'[2]01_ALLCB基本資料'!C:U,16,FALSE) -> 43847 | H29: 償還銀行借款
A30: 1436 | B30: 14362 | C30: 華友聯二 | D30: =IFERROR(VLOOKUP(B30,[1]最高價!$A:$C,3,FALSE),"") -> 600 | E30: =IFERROR(VLOOKUP(B30,[1]最低價!$A:$C,3,FALSE),"") -> 111.1 | F30: 償還銀行借款10.14億 | G30: =VLOOKUP(B30,'[2]01_ALLCB基本資料'!C:U,16,FALSE) -> 44166 | H30: 償還銀行借款
A31: 1436 | B31: 14363 | C31: 華友聯三 | D31: =IFERROR(VLOOKUP(B31,[1]最高價!$A:$C,3,FALSE),"") -> 124.25 | E31: =IFERROR(VLOOKUP(B31,[1]最低價!$A:$C,3,FALSE),"") -> 93.6 | F31: 償還銀行借款6億 | G31: =VLOOKUP(B31,'[2]01_ALLCB基本資料'!C:U,16,FALSE) -> 45531 | H31: 償還銀行借款
A32: 1436 | B32: 14364 | C32: 華友聯四 | D32: =IFERROR(VLOOKUP(B32,[1]最高價!$A:$C,3,FALSE),"") -> 104.95 | E32: =IFERROR(VLOOKUP(B32,[1]最低價!$A:$C,3,FALSE),"") -> 92.5 | F32: 償還銀行借款20.2億，發行CB4共20000張，詢圈101元 | G32: =VLOOKUP(B32,'[2]01_ALLCB基本資料'!C:U,16,FALSE) -> 45734 | H32: 借新還舊
A33: 1437 | B33: 14371 | C33: 勤益一 | D33: =IFERROR(VLOOKUP(B33,[1]最高價!$A:$C,3,FALSE),"") -> 266 | E33: =IFERROR(VLOOKUP(B33,[1]最低價!$A:$C,3,FALSE),"") -> 92 | G33: =VLOOKUP(B33,'[2]01_ALLCB基本資料'!C:U,16,FALSE)
A34: 1438 | B34: 14381 | C34: 三地開發一 | D34: =IFERROR(VLOOKUP(B34,[1]最高價!$A:$C,3,FALSE),"") -> 134 | E34: =IFERROR(VLOOKUP(B34,[1]最低價!$A:$C,3,FALSE),"") -> 119 | F34: 償還銀行借款7.64億，支付營建工程款-艾美新時代(台南市平實段)24.84億，支付營建工程款-艾美‧柏(高雄市後港東段)9.87億。 | G34: =VLOOKUP(B34,'[2]01_ALLCB基本資料'!C:U,16,FALSE) -> 45645 | H34: 償還銀行借款
A35: 1442 | B35: 14422 | C35: 名軒二 | D35: =IFERROR(VLOOKUP(B35,[1]最高價!$A:$C,3,FALSE),"") -> 165 | E35: =IFERROR(VLOOKUP(B35,[1]最低價!$A:$C,3,FALSE),"") -> 105.55 | F35: 償還銀行借款8億 | G35: =VLOOKUP(B35,'[2]01_ALLCB基本資料'!C:U,16,FALSE) -> 41122 | H35: 償還銀行借款
A36: 1442 | B36: 14423 | C36: 名軒三 | D36: =IFERROR(VLOOKUP(B36,[1]最高價!$A:$C,3,FALSE),"") -> 188 | E36: =IFERROR(VLOOKUP(B36,[1]最低價!$A:$C,3,FALSE),"") -> 105 | F36: 償還銀行借款6.26億 | G36: =VLOOKUP(B36,'[2]01_ALLCB基本資料'!C:U,16,FALSE) -> 42339 | H36: 償還銀行借款
A37: 1457 | B37: 14571 | C37: 宜進一 | D37: =IFERROR(VLOOKUP(B37,[1]最高價!$A:$C,3,FALSE),"") -> 109.8 | E37: =IFERROR(VLOOKUP(B37,[1]最低價!$A:$C,3,FALSE),"") -> 90 | F37: 現金增資4.5億，宜進一募得3億，購置土地、廠房及生產設備21.67億 | G37: =VLOOKUP(B37,'[2]01_ALLCB基本資料'!C:U,16,FALSE) -> 40724 | H37: 資本支出
A38: 1464 | B38: 14641 | C38: 得力一 | D38: =IFERROR(VLOOKUP(B38,[1]最高價!$A:$C,3,FALSE),"") -> 172 | E38: =IFERROR(VLOOKUP(B38,[1]最低價!$A:$C,3,FALSE),"") -> 107 | F38: 償還銀行借款4.5億，與得力二同時發行 | G38: =VLOOKUP(B38,'[2]01_ALLCB基本資料'!C:U,16,FALSE) -> 42144 | H38: 償還銀行借款
A39: 1464 | B39: 14642 | C39: 得力二 | D39: =IFERROR(VLOOKUP(B39,[1]最高價!$A:$C,3,FALSE),"") -> 177 | E39: =IFERROR(VLOOKUP(B39,[1]最低價!$A:$C,3,FALSE),"") -> 103 | F39: 償還銀行借款4.5億，與得力一同時發行 | G39: =VLOOKUP(B39,'[2]01_ALLCB基本資料'!C:U,16,FALSE) -> 42145 | H39: 償還銀行借款
A40: 1466 | B40: 14661 | C40: 聚隆一 | D40: =IFERROR(VLOOKUP(B40,[1]最高價!$A:$C,3,FALSE),"") -> 127 | E40: =IFERROR(VLOOKUP(B40,[1]最低價!$A:$C,3,FALSE),"") -> 98 | F40: 機器設備及增設附屬工程1.09億，償還銀行借款1.9億 | G40: =VLOOKUP(B40,'[2]01_ALLCB基本資料'!C:U,16,FALSE) -> 40693 | H40: 償還銀行借款
...

Sheet 01_ALLCB基本資料
A1: 序號 | B1: 股票代號 | C1: CB代號 | D1: 名稱 | E1: 信用評等 | F1: 擔保 | G1: 發行規模 | H1: 轉換價格 | I1: 發行年期 | J1: 詢圈競拍 | K1: 發行券商 | L1: 產業分類 | M1: 產業地位 | N1: 股本大小 | O1: 發行價格 | P1: 到期還本價格 | Q1: 訂價溢價率 | R1: 掛牌日期 | S1: 到期日期 | T1: 掛牌最高 | U1: 掛牌最低
A2: 1 | B2: 1101 | C2: 11011 | D2: 台泥一永 | E2: 4 | F2: 無擔保 | G2: 80 | H2: 36.5 | I2: 5 | J2: 詢圈 | K2: 元大證券 | L2: 水泥工業 | M2: 台灣最大水泥廠 | N2: 775 | O2: 100 | P2: 100 | Q2: 1.0918 | R2: 45636 | S2: 47462 | T2: 108.1 | U2: 94.4
A3: 2 | B3: 1210 | C3: 12101 | D3: 大成一 | E3: 0 | F3: 0 | G3: 10 | H3: 33.59 | I3: 5 | J3: 詢圈 | L3: 食品工業 | M3: 兩岸最大白肉雞電宰加工廠及飼料大廠 | R3: 39336 | S3: 2012/09/11 | T3: 127 | U3: 72.5
A4: 3 | B4: 1216 | C4: 12161 | D4: 統一一 | E4: 0 | G4: 50 | H4: 48.6 | I4: 3 | J4: 詢圈 | L4: 食品工業 | M4: 台灣食品業龍頭廠之一 | R4: 39370 | S4: 2010/10/15 | T4: 106.75 | U4: 91.2
A5: 4 | B5: 1217 | C5: 12171 | D5: 愛之味一 | E5: 0 | G5: 11 | H5: 13.9 | I5: 3 | J5: 詢圈 | L5: 食品工業 | M5: 以飲料、傳統類罐頭為主的食品商 | R5: 40664 | S5: 2014/05/01 | T5: 123 | U5: 100
A6: 5 | B6: 1217 | C6: 12172 | D6: 愛之味二 | E6: 0 | G6: 3 | H6: 13.9 | I6: 5 | J6: 詢圈 | K6: 台新證券 | L6: 食品工業 | M6: 以飲料、傳統類罐頭為主的食品商 | O6: 100 | P6: 100 | R6: 40675 | S6: 42502 | T6: 112 | U6: 89
A7: 6 | B7: 1217 | C7: 12173 | D7: 愛之味三 | E7: 7 | F7: 無擔保 | G7: 10 | H7: 10.9 | I7: 5 | J7: 詢圈 | K7: 台新證券 | L7: 食品工業 | M7: 以飲料、傳統類罐頭為主的食品商 | N7: 49.5 | O7: 100 | P7: 100 | Q7: 1.0139 | R7: 41340 | S7: 43166 | T7: 105 | U7: 99.6
A8: 7 | B8: 1218 | C8: 12181 | D8: 泰山一 | E8: 新光銀行 | F8: 有擔保 | G8: 5 | H8: 15.1 | I8: 3 | J8: 詢圈 | K8: 群益證券 | L8: 食品工業 | M8: 台灣油脂、飲料大廠及轉投資全家便利超商 | N8: 50 | O8: 100 | P8: 100 | Q8: 1.0155 | R8: 41417 | S8: 42513 | T8: 109.9 | U8: 99
A9: 8 | B9: 1225 | C9: 12251 | D9: 福脂一 | E9: 0 | G9: 5 | H9: 14 | I9: 5 | J9: 詢圈 | L9: 食品工業 | M9: 台灣油脂、飼料大廠 | R9: 40158 | S9: 2014/12/11 | T9: 233 | U9: 101
A10: 9 | B10: 1258 | C10: 12581 | D10: 其祥一K | H10: 38.8 | J10: 詢圈 | K10: 台中銀證 | P10: 100 | R10: 42262 | S10: 43358 | T10: 124.25 | U10: 99.1
A11: 10 | B11: 1258 | C11: 12582 | D11: 其祥二K | H11: 30 | J11: 詢圈 | K11: 國票證券 | P11: 100 | R11: 43353 | S11: 45179 | T11: 101.3 | U11: 76.2
A12: 11 | B12: 1312 | C12: 13121 | D12: 國喬一 | I12: 3 | J12: 詢圈 | L12: 塑膠工業 | M12: 台灣第二大SM及ABS廠 | T12: 171 | U12: 90
A13: 12 | B13: 1316 | C13: 13161 | D13: 上曜一 | E13: 板信商銀 | F13: 有擔保 | G13: 3 | H13: 24.9 | I13: 3 | J13: 詢圈 | K13: 元大證券 | L13: 建材營造業 | M13: 上曜集團旗下豪宅品牌 | N13: 27.9 | Q13: 1.01 | R13: 40757 | S13: 2014/07/23 | T13: 122 | U13: 99.65
A14: 13 | B14: 1316 | C14: 13162 | D14: 上曜二 | E14: 板信商銀 | F14: 有擔保 | G14: 2 | H14: 12 | I14: 3 | J14: 詢圈 | K14: 元富證券 | L14: 建材營造業 | M14: 上曜集團旗下豪宅品牌 | N14: 27.9 | O14: 100 | P14: 100 | Q14: 1.0161 | R14: 41996 | S14: 43092 | T14: 177 | U14: 104
A15: 14 | B15: 1316 | C15: 13163 | D15: 上曜三 | E15: 元大銀行 | F15: 有擔保 | G15: 5 | H15: 20.1 | I15: 3 | J15: 詢圈 | K15: 元富證券 | L15: 建材營造業 | M15: 上曜集團旗下豪宅品牌 | N15: 27.9 | O15: 100 | P15: 100 | Q15: 1.1519 | R15: 43411 | S15: 44507 | T15: 117.95 | U15: 99.6
A16: 15 | B16: 1316 | C16: 13164 | D16: 上曜四 | E16: 日盛銀行 | F16: 有擔保 | G16: 4 | H16: 14.9 | I16: 5 | J16: 詢圈 | K16: 富邦證券 | L16: 建材營造業 | M16: 上曜集團旗下豪宅品牌 | N16: 27.9 | O16: 101 | P16: 100 | Q16: 1.2 | R16: 44225 | S16: 46051 | T16: 189 | U16: 101.5
A17: 16 | B17: 1316 | C17: 13165 | D17: 上曜五 | E17: 8 | F17: 無擔保 | G17: 4 | H17: 12.6 | I17: 3 | J17: 詢圈 | K17: 富邦證券 | L17: 建材營造業 | M17: 上曜集團旗下豪宅品牌 | N17: 27.9 | O17: 100 | P17: 100 | Q17: 1.02 | R17: 44228 | S17: 45323 | T17: 232 | U17: 99.6
A18: 17 | B18: 1316 | C18: 13166 | D18: 上曜六 | E18: 板信銀行 | F18: 有擔保 | G18: 4 | H18: 17.8 | I18: 3 | J18: 競拍 | K18: 元富證券 | O18: 100 | P18: 100 | Q18: 1.1995 | R18: 45653 | S18: 46748 | T18: 125.5 | U18: 102.8
A19: 18 | B19: 1319 | C19: 13191 | D19: 東陽一 | E19: 0 | G19: 10 | H19: 50.9 | I19: 5 | J19: 詢圈 | L19: 汽車工業 | M19: 全球第一大汽車AM塑膠件製造商 | R19: 40536 | S19: 2015/12/24 | T19: 115 | U19: 95.4
A20: 19 | B20: 1336 | C20: 13361 | D20: 台翰一 | E20: 台灣中小企 | F20: 有擔保 | G20: 3.5 | H20: 16.58 | I20: 3 | J20: 詢圈 | K20: 國泰證券 | L20: 電子零組件業 | M20: 宣德轉投資之消費電子產品外殼製造商 | N20: 7.88 | O20: 100.5 | P20: 103.03 | Q20: 1.0303 | R20: 41892 | S20: 42988 | T20: 116 | U20: 101.1
A21: 20 | B21: 1337 | C21: 13371 | D21: 再生一 | E21: 4 | F21: 無擔保 | G21: 6 | H21: 101.6 | I21: 3 | J21: 詢圈 | K21: 元大證券 | L21: 塑膠工業 | M21: 大陸第一大EVA發泡材商 | N21: 26.9 | Q21: 1.05 | R21: 41193 | S21: 2015/10/01 | T21: 120.5 | U21: 82.95
A22: 21 | B22: 1338 | C22: 13381 | D22: 廣華一K | E22: 5 | F22: 無擔保 | G22: 6 | H22: 68.8 | I22: 5 | J22: 詢圈 | K22: 國票證券 | L22: 汽車工業 | M22: 汽車OEM塑膠內飾件大廠，供應以大陸市場為主 | N22: 8.38 | O22: 100 | P22: 100 | Q22: 1.0208 | R22: 44215 | S22: 46041 | T22: 117 | U22: 97.1
A23: 22 | B23: 1338 | C23: 13382 | D23: 廣華二K | E23: 5 | F23: 無擔保 | G23: 6 | H23: 39.4 | I23: 5 | J23: 詢圈 | K23: 國票證券 | L23: 汽車工業 | M23: 汽車OEM塑膠內飾件大廠，供應以大陸市場為主 | N23: 8.38 | O23: 100 | P23: 100 | Q23: 1.051 | R23: 45261 | S23: 47088 | T23: 115.5 | U23: 93.05
A24: 23 | B24: 1341 | C24: 13411 | D24: 富林一K | E24: 6 | F24: 無擔保 | G24: 1.5 | H24: 75.8 | I24: 3 | J24: 競拍 | K24: 中信證券 | L24: 塑膠工業 | M24: 越南第一大PVC人造皮革生產商 | N24: 5.17 | O24: 115 | P24: 101.51 | Q24: 1.0218 | R24: 44329 | S24: 45425 | T24: 116.9 | U24: 100.8
A25: 24 | B25: 1342 | C25: 13421 | D25: 八貫一 | E25: 華南銀行 | F25: 有擔保 | G25: 2 | H25: 72 | I25: 3 | J25: 競拍 | K25: 元大證券 | L25: 其他業 | M25: 台灣機能性皮布料及薄膜製造商 | N25: 7.13 | O25: 112.93 | P25: 100 | Q25: 1.0381 | R25: 44714 | S25: 45810 | T25: 243 | U25: 106.5
A26: 25 | B26: 1409 | C26: 14093 | D26: 新纖三 | E26: 0 | G26: 22 | H26: 9.93 | I26: 5 | J26: 詢圈 | L26: 紡織纖維 | M26: 新光集團旗下，台灣知名化纖廠 | R26: 39189 | S26: 2012/04/17 | T26: 180 | U26: 77
A27: 26 | B27: 1432 | C27: 14321 | D27: 大魯閣一 | E27: 有擔保 | F27: 有擔保 | G27: 2.5 | H27: 20.1 | I27: 3 | J27: 詢圈 | K27: 元大證券 | L27: 運動休閒 | M27: 經營型娛樂購物中心事業 | N27: 9 | O27: 100 | P27: 103.8 | Q27: 1.0177 | R27: 42047 | S27: 43143 | T27: 119 | U27: 100.5
A28: 27 | B28: 1432 | C28: 14322 | D28: 大魯閣二 | E28: 8 | F28: 無擔保 | G28: 2.5 | H28: 20.1 | I28: 5 | J28: 詢圈 | K28: 元大證券 | L28: 運動休閒 | M28: 經營型娛樂購物中心事業 | N28: 9 | O28: 100 | P28: 100 | Q28: 1.01 | R28: 42048 | S28: 43874 | T28: 119.1 | U28: 92.3
A29: 28 | B29: 1436 | C29: 14361 | D29: 華友聯一 | E29: 第一銀行 | F29: 有擔保 | G29: 3 | H29: 40 | I29: 5 | J29: 競拍 | K29: 第一金證 | L29: 建材營造業 | M29: 以市地重劃為基礎且針對首購族市場的建商 | N29: 9.8 | O29: 107.73 | P29: 100 | Q29: 1.0521 | R29: 43847 | S29: 45674 | T29: 695 | U29: 106
A30: 29 | B30: 1436 | C30: 14362 | D30: 華友聯二 | E30: 第一銀行 | F30: 有擔保 | G30: 10 | H30: 42 | I30: 5 | J30: 詢圈 | K30: 第一金證 | L30: 建材營造業 | M30: 以市地重劃為基礎且針對首購族市場的建商 | N30: 9.8 | O30: 101 | P30: 100 | Q30: 1.0805 | R30: 44166 | S30: 45992 | T30: 600 | U30: 111.1
A31: 30 | B31: 1436 | C31: 14363 | D31: 華友聯三 | E31: 8 | F31: 無擔保 | G31: 6 | H31: 182.5 | I31: 3 | J31: 詢圈 | K31: 國泰證券 | L31: 建材營造業 | M31: 以市地重劃為基礎且針對首購族市場的建商 | N31: 11.4 | O31: 100 | P31: 104.5678 | Q31: 1.051 | R31: 45531 | S31: 46626 | T31: 124.25 | U31: 93.6
A32: 31 | B32: 1436 | C32: 14364 | D32: 華友聯四 | E32: 8 | F32: 無擔保 | G32: 20 | H32: 140.3 | I32: 3 | J32: 詢圈 | K32: 國泰證券 | L32: 建材營造業 | M32: 以市地重劃為基礎且針對首購族市場的建商 | N32: 11.4 | O32: 101 | P32: 104.5678 | Q32: 1.02 | R32: 45734 | S32: 46830 | T32: 104.95 | U32: 92.5
A33: 32 | B33: 1437 | C33: 14371 | D33: 勤益一 | E33: 0 | I33: 5 | J33: 詢圈 | L33: 其他業 | M33: 投資控股公司，從事地產、紡織貿易及投資事業 | T33: 266 | U33: 92
A34: 33 | B34: 1438 | C34: 14381 | D34: 三地開發一 | E34: 有擔保 | F34: 有擔保 | G34: 10 | H34: 57.5 | I34: 5 | J34: 競拍 | K34: 統一證券 | L34: 建材營造業 | M34: 開發以台南及高雄地區為主力的建商 | N34: 9.12 | O34: 117.63 | P34: 102.5251 | Q34: 1.0201 | R34: 45645 | S34: 47471 | T34: 134 | U34: 119
A35: 34 | B35: 1442 | C35: 14422 | D35: 名軒二 | E35: 台銀 | F35: 有擔保 | G35: 8 | H35: 26.5 | I35: 3 | J35: 詢圈 | K35: 凱基證券 | L35: 建材營造業 | M35: 麗寶集團旗下成員 | N35: 36.6 | Q35: 1.0271 | R35: 41122 | S35: 2015/07/22 | T35: 165 | U35: 105.55
A36: 35 | B36: 1442 | C36: 14423 | D36: 名軒三 | E36: 台灣銀行 | F36: 有擔保 | G36: 8 | H36: 17.9 | I36: 5 | J36: 詢圈 | K36: 凱基證券 | L36: 建材營造業 | M36: 麗寶集團旗下成員 | N36: 36.6 | O36: 100 | P36: 100 | Q36: 1.0142 | R36: 42339 | S36: 44166 | T36: 188 | U36: 105
A37: 36 | B37: 1457 | C37: 14571 | D37: 宜進一 | E37: 7 | F37: 無擔保 | G37: 3 | H37: 10 | I37: 3 | J37: 詢圈 | K37: 福邦證券 | L37: 紡織纖維 | M37: 台灣前五大加工絲廠之一 | N37: 30.2 | Q37: 1.0162 | R37: 40724 | S37: 2014/06/20 | T37: 109.8 | U37: 90
A38: 37 | B38: 1464 | C38: 14641 | D38: 得力一 | E38: 合庫銀行 | F38: 有擔保 | G38: 2 | H38: 24.6 | I38: 3 | J38: 詢圈 | K38: 合庫證券 | L38: 紡織纖維 | M38: 台灣老牌織染一貫化布廠 | N38: 40.8 | O38: 100 | P38: 0 | Q38: 1.04 | R38: 42144 | S38: 43240 | T38: 172 | U38: 107
A39: 38 | B39: 1464 | C39: 14642 | D39: 得力二 | E39: 6 | F39: 無擔保 | G39: 2.5 | H39: 24 | I39: 3 | J39: 詢圈 | K39: 合庫證券 | L39: 紡織纖維 | M39: 台灣老牌織染一貫化布廠 | N39: 40.8 | O39: 100 | P39: 0 | Q39: 1.017 | R39: 42145 | S39: 43241 | T39: 177 | U39: 103
A40: 39 | B40: 1466 | C40: 14661 | D40: 聚隆一 | E40: 合庫擔 | F40: 有擔保 | G40: 3 | H40: 32.8 | I40: 3 | J40: 詢圈 | K40: 元大證券 | L40: 紡織纖維 | M40: 台灣第二大的尼龍加工絲廠 | N40: 11.1 | Q40: 1.011 | R40: 40693 | S40: 2014/05/20 | T40: 127 | U40: 98
...

Sheet 02_ALLCB發行時程
A1: 序號 | B1: 股票代號 | C1: CB代號 | D1: 名稱 | E1: 掛牌日期 | F1: 到期日期 | G1: 董事會公告 | H1: 送件日期 | I1: 生效日期 | J1: 詢圈競拍日期 | K1: 代收價款公告 | L1: 掛牌日期 | M1: CBAS拆解日
A2: 1 | B2: 1101 | C2: 11011 | D2: 台泥一永 | E2: 45636 | F2: 47462 | G2: 45548 | H2: 2024/09/30 | I2: 2024/10/21 | J2: 11/26-11/28 | K2: 45621 | L2: 45636 | M2: 45643
A3: 2 | B3: 1210 | C3: 12101 | D3: 大成一 | E3: 39336 | F3: 2012/09/11
A4: 3 | B4: 1216 | C4: 12161 | D4: 統一一 | E4: 39370 | F4: 2010/10/15
A5: 4 | B5: 1217 | C5: 12171 | D5: 愛之味一 | E5: 40664 | F5: 2014/05/01
A6: 5 | B6: 1217 | C6: 12172 | D6: 愛之味二 | E6: 40675 | F6: 42502
A7: 6 | B7: 1217 | C7: 12173 | D7: 愛之味三 | E7: 41340 | F7: 43166 | H7: 41211 | I7: 41227 | J7: 2/21-2/23 | L7: 41340
A8: 7 | B8: 1218 | C8: 12181 | D8: 泰山一 | E8: 41417 | F8: 42513 | H8: 41374 | I8: 41403 | J8: 5/13-5/14 | L8: 41417
A9: 8 | B9: 1225 | C9: 12251 | D9: 福脂一 | E9: 40158 | F9: 2014/12/11
A10: 9 | B10: 1258 | C10: 12581 | D10: 其祥一KY | E10: 42262 | F10: 43358
A11: 10 | B11: 1258 | C11: 12582 | D11: 其祥二KY | E11: 43353 | F11: 45179
A12: 11 | B12: 1312 | C12: 13121 | D12: 國喬一
A13: 12 | B13: 1316 | C13: 13161 | D13: 上曜一 | E13: 40757 | F13: 2014/07/23 | L13: 40757
A14: 13 | B14: 1316 | C14: 13162 | D14: 上曜二 | E14: 41996 | F14: 43092 | H14: 41912 | I14: 41941 | J14: 12/10-12/11 | L14: 41996
A15: 14 | B15: 1316 | C15: 13163 | D15: 上曜三 | E15: 43411 | F15: 44507 | H15: 2018/09/26 | I15: 2018/10/15 | J15: 10/25-10/26 | L15: 43411
A16: 15 | B16: 1316 | C16: 13164 | D16: 上曜四 | E16: 44225 | F16: 46051 | G16: 44172 | H16: 2020/12/14 | I16: 2020/12/30 | J16: 1/18-1/19 | K16: 44211 | L16: 44225
A17: 16 | B17: 1316 | C17: 13165 | D17: 上曜五 | E17: 44228 | F17: 45323 | G17: 44172 | H17: 2020/12/14 | I17: 2020/12/30 | J17: 1/18-1/19 | K17: 44211 | L17: 44228
A18: 17 | B18: 1316 | C18: 13166 | D18: 上曜六 | E18: 45653 | F18: 46748 | J18: 12/12-12/16 | L18: 45653 | M18: 45663
A19: 18 | B19: 1319 | C19: 13191 | D19: 東陽一 | E19: 40536 | F19: 2015/12/24
A20: 19 | B20: 1336 | C20: 13361 | D20: 台翰一 | E20: 41892 | F20: 42988 | H20: 41835 | I20: 41851 | J20: 8/27-8/28 | L20: 41892
A21: 20 | B21: 1337 | C21: 13371 | D21: 再生一 | E21: 41193 | F21: 2015/10/01 | L21: 41193
A22: 21 | B22: 1338 | C22: 13381 | D22: 廣華一KY | E22: 44215 | F22: 46041 | G22: 44000 | H22: 2020/07/06 | I22: 2020/07/22 | J22: 1/5-1/6 | K22: 44202 | L22: 44215
A23: 22 | B23: 1338 | C23: 13382 | D23: 廣華二KY | E23: 45261 | F23: 47088 | G23: 45166 | H23: 2023/10/17 | I23: 2023/11/02 | J23: 11/16-11/17 | K23: 45253 | L23: 45261 | M23: 45268
A24: 23 | B24: 1341 | C24: 13411 | D24: 富林一KY | E24: 44329 | F24: 45425 | G24: 44266 | H24: 2021/03/30 | I24: 2021/04/19 | J24: 4/27-4/29 | K24: 44307 | L24: 44329
A25: 24 | B25: 1342 | C25: 13421 | D25: 八貫一 | E25: 44714 | F25: 45810 | G25: 44616 | H25: 2022/04/13 | I25: 2022/04/29 | J25: 5/18-5/20 | K25: 44697 | L25: 44714 | M25: 44722
A26: 25 | B26: 1409 | C26: 14093 | D26: 新纖三 | E26: 39189 | F26: 2012/04/17
A27: 26 | B27: 1432 | C27: 14321 | D27: 大魯閣一 | E27: 42047 | F27: 43143 | H27: 41999 | I27: 42030 | J27: 1/30-2/2 | L27: 42047
A28: 27 | B28: 1432 | C28: 14322 | D28: 大魯閣二 | E28: 42048 | F28: 43874 | H28: 41999 | I28: 42030 | J28: 1/30-2/2 | L28: 42048
A29: 28 | B29: 1436 | C29: 14361 | D29: 華友聯一 | E29: 43847 | F29: 45674 | G29: 43777 | H29: 2019/12/10 | I29: 2019/12/26 | J29: 1/2-1/6 | K29: 43826 | L29: 43847
A30: 29 | B30: 1436 | C30: 14362 | D30: 華友聯二 | E30: 44166 | F30: 45992 | G30: 43910 | H30: 44081 | I30: 44097 | J30: 11/18-11/19 | K30: 44158 | L30: 44166
A31: 30 | B31: 1436 | C31: 14363 | D31: 華友聯三 | E31: 45531 | F31: 46626 | G31: 45422 | H31: 2024/07/01 | I31: 2024/07/17 | J31: 8/12-8/14 | K31: 45444 | L31: 45531 | M31: 45538
A32: 31 | B32: 1436 | C32: 14364 | D32: 華友聯四 | E32: 45734 | F32: 46830 | G32: 45597 | H32: 2024/12/13 | I32: 2024/12/31 | J32: 3/4-3/6 | K32: 45715 | L32: 45734 | M32: 45376
A33: 32 | B33: 1437 | C33: 14371 | D33: 勤益一
A34: 33 | B34: 1438 | C34: 14381 | D34: 三地開發一 | E34: 45645 | F34: 47471 | G34: 45488 | H34: 2024/10/21 | I34: 2024/11/06 | J34: 12/4-12/6 | K34: 45625 | L34: 45645 | M34: 45652
A35: 34 | B35: 1442 | C35: 14422 | D35: 名軒二 | E35: 41122 | F35: 2015/07/22 | H35: 41089 | I35: 41107 | J35: 7/20-7/23 | L35: 41122
A36: 35 | B36: 1442 | C36: 14423 | D36: 名軒三 | E36: 42339 | F36: 44166 | H36: 42307 | I36: 42325 | J36: 11/19-11/20 | L36: 42339
A37: 36 | B37: 1457 | C37: 14571 | D37: 宜進一 | E37: 40724 | F37: 2014/06/20 | L37: 40724
A38: 37 | B38: 1464 | C38: 14641 | D38: 得力一 | E38: 42144 | F38: 43240 | H38: 42102 | I38: 42118 | J38: 5/5-5/7 | L38: 42144
A39: 38 | B39: 1464 | C39: 14642 | D39: 得力二 | E39: 42145 | F39: 43241 | H39: 42102 | I39: 42118 | J39: 5/5-5/7 | L39: 42145
A40: 39 | B40: 1466 | C40: 14661 | D40: 聚隆一 | E40: 40693 | F40: 2014/05/20 | L40: 40693
...

Sheet 03_ALLCB賣回條件
A1: 序號 | B1: 股票代號 | C1: CB代號 | D1: 名稱 | E1: 賣回日期1 | F1: 賣回日期2 | G1: 投資人提前賣回 | H1: 賣回條件
A2: 1 | B2: 1101 | C2: 11011 | D2: 台泥一永 | E2: 46731 | F2: 47462 | G2: 發行滿三年 | H2: YTP(3)=(0%)
A3: 2 | B3: 1210 | C3: 12101 | D3: 大成一
A4: 3 | B4: 1216 | C4: 12161 | D4: 統一一
A5: 4 | B5: 1217 | C5: 12171 | D5: 愛之味一
A6: 5 | B6: 1217 | C6: 12172 | D6: 愛之味二 | E6: 41406 | F6: 41771 | G6: 發行滿二年、滿三年
A7: 6 | B7: 1217 | C7: 12173 | D7: 愛之味三 | E7: 42070 | F7: 42436 | G7: 到期滿二/年、/三年 | H7: YTP(2,3)=(1.75%)
A8: 7 | B8: 1218 | C8: 12181 | D8: 泰山一 | E8: 42147 | F8: 42513 | G8: 發行滿二年 | H8: YTP(2)=(1%)
A9: 8 | B9: 1225 | C9: 12251 | D9: 福脂一
A10: 9 | B10: 1258 | C10: 12581 | D10: 其祥一KY | E10: 42993 | F10: 43358 | G10: 發行滿二年 | H10: YTP(2)=(1%)
A11: 10 | B11: 1258 | C11: 12582 | D11: 其祥二KY | E11: 44449 | F11: 45179 | G11: 發行滿三年 | H11: YTP(3)=(0.5%)
A12: 11 | B12: 1312 | C12: 13121 | D12: 國喬一
A13: 12 | B13: 1316 | C13: 13161 | D13: 上曜一
A14: 13 | B14: 1316 | C14: 13162 | D14: 上曜二 | E14: 42727 | F14: 43092 | G14: 發行滿二年 | H14: YTP(2)=(1%)
A15: 14 | B15: 1316 | C15: 13163 | D15: 上曜三 | E15: 44142 | F15: 44507 | G15: 發行滿二年 | H15: YTP(2)=(0.5%)
A16: 15 | B16: 1316 | C16: 13164 | D16: 上曜四 | E16: 45320 | F16: 46051 | G16: 發行滿三年 | H16: YTP(3)=(0.25%)
A17: 16 | B17: 1316 | C17: 13165 | D17: 上曜五 | E17: 44958 | F17: 45323 | G17: 發行滿二年 | H17: YTP(2)=(2%)
A18: 17 | B18: 1316 | C18: 13166 | D18: 上曜六 | E18: 46383 | F18: 46748 | G18: 發行滿二年 | H18: YTP(2)=(0.25%)
A19: 18 | B19: 1319 | C19: 13191 | D19: 東陽一
A20: 19 | B20: 1336 | C20: 13361 | D20: 台翰一 | E20: 42623 | F20: 42988 | G20: 發行滿二年 | H20: YTP(2)=(1%)
A21: 20 | B21: 1337 | C21: 13371 | D21: 再生一
A22: 21 | B22: 1338 | C22: 13381 | D22: 廣華一KY | E22: 45310 | F22: 46041 | G22: 發行滿三年 | H22: YTP(3)=(0.5%)
A23: 22 | B23: 1338 | C23: 13382 | D23: 廣華二KY | E23: 46357 | F23: 47088 | G23: 發行滿三年 | H23: YTP(3)=(2%)
A24: 23 | B24: 1341 | C24: 13411 | D24: 富林一KY | E24: 45059 | F24: 45425 | G24: 發行滿二年 | H24: YTM(3)=(0.5%)
A25: 24 | B25: 1342 | C25: 13421 | D25: 八貫一 | E25: 45810 | G25: 無 | H25: YTM(3)=(0%)
A26: 25 | B26: 1409 | C26: 14093 | D26: 新纖三
A27: 26 | B27: 1432 | C27: 14321 | D27: 大魯閣一 | E27: 42778 | F27: 43143 | G27: 發行滿二年 | H27: YTP(2,3)=(1,1.25%)
A28: 27 | B28: 1432 | C28: 14322 | D28: 大魯閣二 | E28: 43144 | F28: 43509 | G28: 發行滿三、四年 | H28: YTP(3,4)=(1.25,1.5%)
A29: 28 | B29: 1436 | C29: 14361 | D29: 華友聯一 | E29: 44943 | F29: 45674 | G29: 發行滿三年 | H29: YTP(3)=(0.5%)
A30: 29 | B30: 1436 | C30: 14362 | D30: 華友聯二 | E30: 45261 | F30: 45992 | G30: 發行滿三年 | H30: YTP(3)=(0.25%)
A31: 30 | B31: 1436 | C31: 14363 | D31: 華友聯三 | E31: 46261 | F31: 46626 | G31: 發行滿二年 | H31: YTP(2)=(1.5%)
A32: 31 | B32: 1436 | C32: 14364 | D32: 華友聯四 | E32: 46464 | F32: 46830 | G32: 發行滿二年 | H32: YTP(2)=(1.5%)
A33: 32 | B33: 1437 | C33: 14371 | D33: 勤益一
A34: 33 | B34: 1438 | C34: 14381 | D34: 三地開發一 | E34: 46740 | F34: 47471 | G34: 發行滿三年 | H34: YTP(3)=(0.5%)
A35: 34 | B35: 1442 | C35: 14422 | D35: 名軒二 | H35: YTP(2)=(1%)，無重設
A36: 35 | B36: 1442 | C36: 14423 | D36: 名軒三 | E36: 43070 | F36: 43435 | G36: 發行滿二、三年 | H36: YTP(2,3)=(1.25%)
A37: 36 | B37: 1457 | C37: 14571 | D37: 宜進一
A38: 37 | B38: 1464 | C38: 14641 | D38: 得力一 | E38: 43240 | G38: 0 | H38: YTP(3)=(0%)
A39: 38 | B39: 1464 | C39: 14642 | D39: 得力二 | E39: 42876 | F39: 43241 | G39: 0 | H39: YTP(2)=(1%)
A40: 39 | B40: 1466 | C40: 14661 | D40: 聚隆一
...

Sheet 04_所有CB競拍資料庫
A1: 序號 | B1: 開標日期 | C1: 股票代號 | D1: CB代號 | E1: 名稱 | F1: 股本 | G1: 發行規模 | H1: 年期 | I1: 擔保 | J1: 信用評等 | K1: 競拍張數 | L1: 底標價 | M1: 截標日 | N1: 截標收盤 | O1: 轉換價 | P1: 訂價溢價率 | Q1: 理論價 | R1: 最低得標 | S1: 最低溢價 | T1: 平均得標 | U1: 平均溢價 | V1: 發行券商 | W1: 產業分類 | X1: 合格件數 | Y1: 投標張數 | Z1: 投標倍數 | AA1: 投標均張 | AB1: 投標開始日 | AC1: 最高投(得)標數量(張) | AD1: 撥券日 | AE1: 得標總金額 | AF1: 得標手續費率(%) | AG1: 最高得標價格(元) | AH1: 承銷價格(元)
A2: 1 | B2: 43546 | C2: 4943 | D2: 49431 | E2: 康控一KY | F2: 15.7 | G2: 15 | H2: 3 | I2: 無擔保 | J2: 9 | K2: 13500 | L2: 100 | M2: 43544 | N2: 124.5 | O2: 121.1 | P2: 1.02 | Q2: 102.81 | R2: 100.5 | S2: -0.0224 | T2: 102.07 | U2: -0.0072 | V2: 中信證券 | W2: 電子零組件業 | X2: 829 | Y2: 19751 | Z2: 1.46 | AA2: 23.83 | AB2: 43542 | AC2: 1350 | AD2: 43557 | AE2: 1377907550 | AF2: 1 | AG2: 159 | AH2: 102.07
A3: 2 | B3: 43710 | C3: 4736 | D3: 47363 | E3: 泰博三 | F3: 9.2 | G3: 15 | H3: 5 | I3: 有擔保 | J3: 4 | K3: 12752 | L3: 100 | M3: 43684 | N3: 126 | O3: 140 | P3: 1.057 | Q3: 90 | R3: 107.17 | S3: 0.1908 | T3: 108.46 | U3: 0.2051 | V3: 凱基證券 | W3: 生技醫療業 | X3: 1559 | Y3: 54356 | Z3: 4.26 | AA3: 34.87 | AB3: 43682 | AC3: 1275 | AD3: 43698 | AE3: 1394223850 | AF3: 0.5 | AG3: 140.1 | AH3: 109.33
A4: 3 | B4: 43773 | C4: 8028 | D4: 80281 | E4: 昇陽一 | F4: 13.2 | G4: 10 | H4: 3 | I4: 無擔保 | J4: 6 | K4: 8732 | L4: 102 | M4: 43769 | N4: 76.8 | O4: 76.1 | P4: 1.02 | Q4: 100.92 | R4: 108.45 | S4: 0.0746 | T4: 109.92 | U4: 0.0892 | V4: 富邦證券 | W4: 半導體業 | X4: 1063 | Y4: 31398 | Z4: 3.6 | AA4: 29.54
A5: 4 | B5: 43801 | C5: 2729 | D5: 27291 | E5: 瓦城一 | F5: 2.3 | G5: 8 | H5: 3 | I5: 無擔保 | J5: 5 | K5: 6880 | L5: 102 | M5: 43797 | N5: 286 | O5: 300 | P5: 1.072 | Q5: 95.33 | R5: 102.81 | S5: 0.0784 | T5: 107.3 | U5: 0.1255 | V5: 富邦證券 | W5: 觀光餐旅 | X5: 674 | Y5: 11341 | Z5: 1.65 | AA5: 16.83
A6: 5 | B6: 43810 | C6: 6477 | D6: 64771 | E6: 安集一 | F6: 11.4 | G6: 3 | H6: 5 | I6: 無擔保 | J6: 6 | K6: 2550 | L6: 100 | M6: 43808 | N6: 22.65 | O6: 23 | P6: 1.02 | Q6: 98.48 | R6: 100.51 | S6: 0.0206 | T6: 101.59 | U6: 0.0316 | V6: 福邦證券 | W6: 光電業 | X6: 187 | Y6: 4116 | Z6: 1.61 | AA6: 22.01 | AB6: 43804 | AC6: 255 | AD6: 43819 | AE6: 259066700 | AF6: 0.5 | AG6: 109.22 | AH6: 101.59
A7: 6 | B7: 43836 | C7: 3617 | D7: 36171 | E7: 碩天一 | F7: 8.1 | G7: 10 | H7: 3 | I7: 無擔保 | J7: 5 | K7: 10200 | L7: 101.5 | M7: 43832 | N7: 113 | O7: 122 | P7: 1.096 | Q7: 92.62 | R7: 104.1 | S7: 0.1239 | T7: 105.23 | U7: 0.1361 | V7: 宏遠證券 | W7: 其他電子業 | X7: 882 | Y7: 24587 | Z7: 2.41 | AA7: 27.88 | AB7: 43829 | AC7: 1020 | AD7: 43845 | AE7: 1073334860 | AF7: 0.5 | AG7: 141 | AH7: 105.23
A8: 7 | B8: 43838 | C8: 1436 | D8: 14361 | E8: 華友聯一 | F8: 9.6 | G8: 3 | H8: 5 | I8: 有擔保 | J8: 8 | K8: 2550 | L8: 100 | M8: 43836 | N8: 40.95 | O8: 40 | P8: 1.052 | Q8: 102.38 | R8: 106.66 | S8: 0.0419 | T8: 107.73 | U8: 0.0523 | V8: 第一金證 | W8: 建材營造業 | X8: 372 | Y8: 7637 | Z8: 2.99 | AA8: 20.53 | AB8: 43832 | AC8: 255 | AD8: 43847 | AE8: 274721790 | AF8: 0.5 | AG8: 120 | AH8: 107.73
A9: 8 | B9: 43839 | C9: 3594 | D9: 35943 | E9: 磐儀三 | F9: 7.2 | G9: 3 | H9: 3 | I9: 無擔保 | J9: 7 | K9: 2550 | L9: 100 | M9: 43837 | N9: 25.45 | O9: 22.8 | P9: 1.02 | Q9: 111.62 | R9: 101.65 | S9: -0.0893 | T9: 104.86 | U9: -0.0606 | V9: 福邦證券 | W9: 電腦及週邊設備業 | X9: 241 | Y9: 4769 | Z9: 1.87 | AA9: 19.79 | AB9: 43833 | AC9: 255 | AD9: 43850 | AE9: 267389720 | AF9: 0.5 | AG9: 115.3 | AH9: 104.86
A10: 9 | B10: 43867 | C10: 4967 | D10: 49671 | E10: 十銓一 | F10: 7.5 | G10: 5 | H10: 3 | I10: 有擔保 | J10: 6 | K10: 4250 | L10: 102 | M10: 43865 | N10: 36.55 | O10: 33.9 | P10: 1.069 | Q10: 107.82 | R10: 110.7 | S10: 0.0267 | T10: 112.21 | U10: 0.0407 | V10: 群益證券 | W10: 半導體業 | X10: 444 | Y10: 11307 | Z10: 2.66 | AA10: 25.47 | AB10: 43861 | AC10: 425 | AD10: 43878 | AE10: 476883600 | AF10: 0.5 | AG10: 119.6 | AH10: 112.21
A11: 10 | B11: 43879 | C11: 2466 | D11: 24663 | E11: 冠希電三 | F11: 15.6 | G11: 3 | H11: 3 | I11: 有擔保 | J11: 8 | K11: 2660 | L11: 102 | M11: 43875 | N11: 34.9 | O11: 38 | P11: 1.08 | Q11: 91.84 | R11: 103.11 | S11: 0.1227 | T11: 104.5 | U11: 0.1378 | V11: 中信證券 | W11: 光電業 | X11: 481 | Y11: 5011 | Z11: 1.88 | AA11: 10.42 | AB11: 43873 | AC11: 266 | AD11: 43888 | AE11: 277980900 | AF11: 0.5 | AG11: 110 | AH11: 104.5
A12: 11 | B12: 43880 | C12: 4175 | D12: 41752 | E12: 杏一二 | F12: 3.2 | G12: 3 | H12: 5 | I12: 無擔保 | J12: 6 | K12: 2550 | L12: 102 | M12: 43878 | N12: 72.9 | O12: 77.3 | P12: 1.05 | Q12: 94.31 | R12: 102.65 | S12: 0.0885 | T12: 103.62 | U12: 0.0987 | V12: 國泰證券 | W12: 生技醫療業 | X12: 190 | Y12: 4108 | Z12: 1.61 | AA12: 21.62 | AB12: 43874 | AC12: 255 | AD12: 43892 | AE12: 264225240 | AF12: 0.5 | AG12: 110 | AH12: 103.62
A13: 12 | B13: 43887 | C13: 2228 | D13: 22282 | E13: 劍麟二 | F13: 7.6 | G13: 3 | H13: 3 | I13: 無擔保 | J13: 5 | K13: 2550 | L13: 100 | M13: 43885 | N13: 95.2 | O13: 106.23 | P13: 1.05 | Q13: 89.62 | R13: 104.5 | S13: 0.1661 | T13: 105.98 | U13: 0.1826 | V13: 元大證券 | W13: 汽車工業 | X13: 416 | Y13: 11327 | Z13: 4.44 | AA13: 27.23 | AB13: 43881 | AC13: 255 | AD13: 43899 | AE13: 270260630 | AF13: 0.5 | AG13: 110 | AH13: 105.98
A14: 13 | B14: 43941 | C14: 6150 | D14: 61504 | E14: 撼訊四 | F14: 4.5 | G14: 4 | H14: 3 | I14: 無擔保 | J14: 8 | K14: 3550 | L14: 100 | M14: 43937 | N14: 42.8 | O14: 34.5 | P14: 1.02 | Q14: 124.06 | R14: 102.22 | S14: -0.176 | T14: 106.83 | U14: -0.1389 | V14: 宏遠證券 | W14: 電腦及週邊設備業 | X14: 221 | Y14: 4439 | Z14: 1.25 | AA14: 20.09 | AB14: 43935 | AC14: 355 | AD14: 43950 | AE14: 379239070 | AF14: 0.5 | AG14: 117.33 | AH14: 106.83
A15: 14 | B15: 43962 | C15: 4919 | D15: 49191 | E15: 新唐一 | F15: 39.1 | G15: 20 | H15: 7 | I15: 無擔保 | J15: 4 | K15: 5361 | L15: 100 | M15: 43958 | N15: 39.15 | O15: 39.9 | P15: 1.083 | Q15: 98.12 | R15: 100 | S15: 0.0192 | T15: 100.91 | U15: 0.0284 | V15: 中信證券 | W15: 半導體業 | X15: 473 | Y15: 5361 | Z15: 1 | AA15: 11.33 | AB15: 43956 | AC15: 1800 | AD15: 43971 | AE15: 540953740 | AF15: 0.5 | AG15: 110 | AH15: 100
A16: 15 | B16: 43979 | C16: 6189 | D16: 61893 | E16: 豐藝三 | F16: 18.3 | G16: 10 | H16: 3 | I16: 無擔保 | J16: 4 | K16: 3740 | L16: 101 | M16: 43977 | N16: 34.4 | O16: 34.5 | P16: 1.021 | Q16: 99.71 | R16: 101 | S16: 0.0129 | T16: 103.94 | U16: 0.0424 | V16: 群益證券 | W16: 電子通路業 | X16: 192 | Y16: 3740 | Z16: 1 | AA16: 19.48 | AB16: 43973 | AC16: 850 | AD16: 43990 | AE16: 388726950 | AF16: 0.5 | AG16: 498 | AH16: 101
A17: 16 | B17: 44043 | C17: 9958 | D17: 99584 | E17: 世紀鋼四 | F17: 23.1 | G17: 15 | H17: 3 | I17: 無擔保 | J17: 5 | K17: 10544 | L17: 100 | M17: 44041 | N17: 92.8 | O17: 90.88 | P17: 1.02 | Q17: 102.11 | R17: 100 | S17: -0.0207 | T17: 101.13 | U17: -0.0096 | V17: 群益證券 | W17: 鋼鐵工業 | X17: 426 | Y17: 10544 | Z17: 1 | AA17: 24.75 | AB17: 44039 | AC17: 1275 | AD17: 44054 | AE17: 1066290440 | AF17: 0.5 | AG17: 110 | AH17: 100
... A37: 36 | B37: 44322 | C37: 6641 | D37: 66411 | E37: 基士德KY一 | F37: 3.4 | G37: 3 | H37: 3 | I37: 無擔保 | J37: 5 | K37: 2550 | L37: 100 | M37: 44320 | N37: 71.6 | O37: 76 | P37: 1.05 | Q37: 94.21 | R37: 101.5 | S37: 0.0774 | T37: 104.64 | U37: 0.1107 | V37: 永豐金證 | W37: 綠能環保 | X37: 189 | Y37: 3666 | Z37: 1.44 | AA37: 19.4 | AB37: 44315 | AC37: 255 | AD37: 44333 | AE37: 266842900 | AF37: 0.5 | AG37: 138 | AH37: 104.64
A38: 37 | B38: 44349 | C38: 6015 | D38: 60151 | E38: 宏遠一 | F38: 33.1 | G38: 7 | H38: 5 | I38: 無擔保 | J38: BBB | K38: 7000 | L38: 100 | M38: 44347 | N38: 25.15 | O38: 19.18 | P38: 1.02 | Q38: 131.13 | R38: 114.7 | S38: -0.1253 | T38: 117.8 | U38: -0.1016 | V38: 凱基證券 | W38: 證券業 | X38: 747 | Y38: 21079 | Z38: 3.01 | AA38: 28.22 | AB38: 44343 | AC38: 700 | AD38: 44358 | AE38: 824581730 | AF38: 0.5 | AG38: 151.3 | AH38: 117.8
A39: 38 | B39: 44357 | C39: 6179 | D39: 61792 | E39: 亞通二 | F39: 7.4 | G39: 2 | H39: 3 | I39: 有擔保 | J39: 6 | K39: 1700 | L39: 101 | M39: 44357 | N39: 32.75 | O39: 32.9 | P39: 1.02 | Q39: 99.54 | R39: 114.33 | S39: 0.1485 | T39: 115.29 | U39: 0.1582 | V39: 兆豐證券 | W39: 其他業 | X39: 613 | Y39: 11047 | Z39: 6.5 | AA39: 18.02 | AB39: 44351 | AC39: 170 | AD39: 44369 | AE39: 195992260 | AF39: 0.5 | AG39: 125 | AH39: 115.29
A40: 39 | B40: 44378 | C40: 2482 | D40: 24822 | E40: 連宇二 | F40: 6.2 | G40: 2 | H40: 3 | I40: 有擔保 | J40: 7 | K40: 1700 | L40: 100 | M40: 44378 | N40: 12.5 | O40: 12.65 | P40: 1.025 | Q40: 98.81 | R40: 112.8 | S40: 0.1415 | T40: 114.15 | U40: 0.1552 | V40: 國票證券 | W40: 其他電子業 | X40: 311 | Y40: 6224 | Z40: 3.66 | AA40: 20.01 | AB40: 44372 | AC40: 170 | AD40: 44389 | AE40: 194053150 | AF40: 0.5 | AG40: 117.71 | AH40: 114.15
A41: 40 | B41: 44385 | C41: 6541 | D41: 65481 | E41: 長科一 | F41: 31.2 | G41: 15 | H41: 5 | I41: 有擔保 | J41: 7 | K41: 12750 | L41: 102 | M41: 44383 | N41: 83.1 | O41: 75 | P41: 1.042 | Q41: 110.8 | R41: 118.28 | S41: 0.0675 | T41: 120.56 | U41: 0.0881 | V41: 凱基證券 | W41: 生技醫療業 | X41: 1154 | Y41: 41071 | Z41: 3.22 | AA41: 35.59 | AB41: 44379 | AC41: 1275 | AD41: 44396 | AE41: 1537201910 | AF41: 0.5 | AG41: 128 | AH41: 120.56
A42: 41 | B42: 44386 | C42: 8109 | D42: 81091 | E42: 博大一 | F42: 7.8 | G42: 3 | H42: 3 | I42: 無擔保 | J42: 5 | K42: 2550 | L42: 100 | M42: 44384 | N42: 72.7 | O42: 74 | P42: 1.021 | Q42: 98.24 | R42: 109.8 | S42: 0.1176 | T42: 111.42 | U42: 0.1341 | V42: 凱基證券 | W42: 電子零組件業 | X42: 559 | Y42: 12744 | Z42: 5 | AA42: 22.8 | AB42: 44382 | AC42: 255 | AD42: 44397 | AE42: 284123890 | AF42: 0.5 | AG42: 116.23 | AH42: 111.42
A43: 42 | B43: 44400 | C43: 2338 | D43: 23383 | E43: 光罩三 | F43: 25.3 | G43: 20 | H43: 5 | I43: 無擔保 | J43: 7 | K43: 17200 | L43: 102 | M43: 44398 | N43: 99 | O43: 88.8 | P43: 1.024 | Q43: 111.49 | R43: 112.56 | S43: 0.0096 | T43: 115.23 | U43: 0.0336 | V43: 凱基證券 | W43: 半導體業 | X43: 1154 | Y43: 33705 | Z43: 1.96 | AA43: 29.21 | AB43: 44396 | AC43: 1720 | AD43: 44411 | AE43: 1981888020 | AF43: 0.5 | AG43: 128 | AH43: 115.23
A44: 43 | B44: 44400 | C44: 3028 | D44: 30284 | E44: 增你強四 | F44: 21.4 | G44: 7 | H44: 3 | I44: 無擔保 | J44: 6 | K44: 5100 | L44: 101 | M44: 44398 | N44: 27.65 | O44: 29 | P44: 1.034 | Q44: 95.34 | R44: 107.33 | S44: 0.1257 | T44: 109.18 | U44: 0.1451 | V44: 群益證券 | W44: 電子通路業 | X44: 562 | Y44: 15559 | Z44: 3.05 | AA44: 27.69 | AB44: 44396 | AC44: 510 | AD44: 44411 | AE44: 556814850 | AF44: 0.5 | AG44: 115.2 | AH44: 109.18
A45: 44 | B45: 44403 | C45: 6477 | D45: 64773 | E45: 安集三 | F45: 11.4 | G45: 5 | H45: 5 | I45: 無擔保 | J45: 6 | K45: 4250 | L45: 100 | M45: 44399 | N45: 45.8 | O45: 45.3 | P45: 1.022 | Q45: 101.1 | R45: 103.88 | S45: 0.0275 | T45: 106.99 | U45: 0.0582 | V45: 福邦證券 | W45: 光電業 | X45: 321 | Y45: 7088 | Z45: 1.67 | AA45: 22.08 | AB45: 44397 | AC45: 425 | AD45: 44412 | AE45: 454703100 | AF45: 0.5 | AG45: 116.5 | AH45: 106.99
A46: 45 | B46: 44403 | C46: 6150 | D46: 61505 | E46: 撼訊五 | F46: 4.5 | G46: 7 | H46: 3 | I46: 無擔保 | J46: 8 | K46: 5950 | L46: 100 | M46: 44399 | N46: 139 | O46: 138.3 | P46: 1.021 | Q46: 100.51 | R46: 100.23 | S46: -0.0027 | T46: 104.29 | U46: 0.0376 | V46: 宏遠證券 | W46: 電腦及週邊設備業 | X46: 333 | Y46: 7459 | Z46: 1.25 | AA46: 22.4 | AB46: 44397 | AC46: 595 | AD46: 44412 | AE46: 620518730 | AF46: 0.5 | AG46: 120 | AH46: 104.29
A47: 46 | B47: 44412 | C47: 6209 | D47: 62092 | E47: 今國光二 | F47: 16.3 | G47: 3.5 | H47: 3 | I47: 有擔保 | J47: 6 | K47: 2975 | L47: 100 | M47: 44410 | N47: 33.6 | O47: 35 | P47: 1.036 | Q47: 96 | R47: 113.3 | S47: 0.1802 | T47: 115.17 | U47: 0.1997 | V47: 國票證券 | W47: 光電業 | X47: 696 | Y47: 12874 | Z47: 4.33 | AA47: 18.5 | AB47: 44406 | AC47: 297 | AD47: 44421 | AE47: 342640330 | AF47: 0.5 | AG47: 123.5 | AH47: 115.17
A48: 47 | B48: 44418 | C48: 3533 | D48: 35331 | E48: 嘉澤一 | F48: 10.3 | G48: 10 | H48: 3 | I48: 無擔保 | J48: 4 | K48: 8800 | L48: 102 | M48: 44414 | N48: 570 | O48: 563.2 | P48: 1.02 | Q48: 101.21 | R48: 114.46 | S48: 0.1309 | T48: 115.45 | U48: 0.1407 | V48: 元大證券 | W48: 電子零組件業 | X48: 1352 | Y48: 37818 | Z48: 4.3 | AA48: 27.97 | AB48: 44412 | AC48: 880 | AD48: 44427 | AE48: 1015932860 | AF48: 0.6 | AG48: 163.5 | AH48: 115.45
A49: 48 | B49: 44432 | C49: 3339 | D49: 33394 | E49: 泰谷四 | F49: 4.3 | G49: 3 | H49: 3 | I49: 有擔保 | J49: 8 | K49: 2550 | L49: 102 | M49: 44428 | N49: 18.8 | O49: 19.8 | P49: 1.02 | Q49: 94.95 | R49: 109.3 | S49: 0.1511 | T49: 110.98 | U49: 0.1688 | V49: 富邦證券 | W49: 光電業 | X49: 315 | Y49: 7618 | Z49: 2.99 | AA49: 24.18 | AB49: 44426 | AC49: 255 | AD49: 44441 | AE49: 282999350 | AF49: 0.5 | AG49: 116.5 | AH49: 110.98
A50: 49 | B50: 44439 | C50: 6203 | D50: 62031 | E50: 海韻一 | F50: 8 | G50: 6 | H50: 3 | I50: 無擔保 | J50: 5 | K50: 5116 | L50: 103.5 | M50: 44435 | N50: 97.2 | O50: 95.8 | P50: 1.02 | Q50: 101.46 | R50: 111.1 | S50: 0.095 | T50: 112.84 | U50: 0.1121 | V50: 富邦證券 | W50: 電子零組件業 | X50: 550 | Y50: 13263 | Z50: 2.59 | AA50: 24.11 | AB50: 44433 | AC50: 511 | AD50: 44448 | AE50: 577269840 | AF50: 0.5 | AG50: 119 | AH50: 112.84
... A172: 171 | B172: 45268 | C172: 8488 | D172: 84881 | E172: 吉源一KY | F172: 6.8 | G172: 3 | H172: 3 | I172: 有擔保 | J172: 7 | K172: 2550 | L172: 101 | M172: 45266 | N172: 18.6 | O172: 18.5 | P172: 1.025 | Q172: 100.54 | R172: 102.71 | S172: 0.0216 | T172: 104.67 | U172: 0.0411 | V172: 玉山證券 | W172: 其他業 | X172: 191 | Y172: 5497 | Z172: 2.16 | AA172: 28.78 | AB172: 45264 | AC172: 255 | AD172: 45279 | AE172: 266913480 | AF172: 0.5 | AG172: 112.83 | AH172: 104.67
A173: 172 | B173: 45286 | C173: 6015 | D173: 60152 | E173: 宏遠證二 | F173: 35.1 | G173: 6 | H173: 5 | I173: 無擔保 | J173: BBB | K173: 6000 | L173: 100 | M173: 45282 | N173: 10.85 | O173: 10.92 | P173: 1.021 | Q173: 99.36 | R173: 100.05 | S173: 0.007 | T173: 101.36 | U173: 0.0201 | V173: 凱基證券 | W173: 證券業 | X173: 200 | Y173: 11413 | Z173: 1.9 | AA173: 57.07 | AB173: 45280 | AC173: 600 | AD173: 45296 | AE173: 608160270 | AF173: 0.5 | AG173: 107.1 | AH173: 101.36
A174: 173 | B174: 45287 | C174: 3548 | D174: 35482 | E174: 兆利二 | F174: 6.6 | G174: 8 | H174: 3 | I174: 無擔保 | J174: 5 | K174: 7200 | L174: 101 | M174: 45285 | N174: 195.5 | O174: 199 | P174: 1.031 | Q174: 98.24 | R174: 112.12 | S174: 0.1413 | T174: 113.2 | U174: 0.1523 | V174: 永豐金證 | W174: 電子零組件業 | X174: 1246 | Y174: 42464 | Z174: 5.9 | AA174: 34.08 | AB174: 45281 | AC174: 720 | AD174: 45299 | AE174: 815044010 | AF174: 0.5 | AG174: 118.91 | AH174: 113.2
A175: 174 | B175: 45300 | C175: 6715 | D175: 67152 | E175: 嘉基二 | F175: 6.3 | G175: 3 | H175: 3 | I175: 無擔保 | J175: 5 | K175: 2550 | L175: 100 | M175: 45296 | N175: 157.5 | O175: 168 | P175: 1.021 | Q175: 93.75 | R175: 113.87 | S175: 0.2146 | T175: 114.74 | U175: 0.2239 | V175: 中信證券 | W175: 電子零組件業 | X175: 848 | Y175: 22565 | Z175: 8.85 | AA175: 26.61 | AB175: 45294 | AC175: 255 | AD175: 45309 | AE175: 292598840 | AF175: 0.5 | AG175: 117.38 | AH175: 114.74
A176: 175 | B176: 45301 | C176: 8210 | D176: 82101 | E176: 勤誠一 | F176: 12.1 | G176: 10 | H176: 3 | I176: 無擔保 | J176: 4 | K176: 8974 | L176: 102 | M176: 45299 | N176: 242.5 | O176: 271 | P176: 1.021 | Q176: 89.48 | R176: 108.1 | S176: 0.208 | T176: 109.69 | U176: 0.2258 | V176: 元大證券 | W176: 電腦及週邊設備業 | X176: 862 | Y176: 32252 | Z176: 3.59 | AA176: 37.42 | AB176: 45295 | AC176: 897 | AD176: 45310 | AE176: 984373650 | AF176: 0.5 | AG176: 158 | AH176: 109.69
A177: 176 | B177: 45302 | C177: 3479 | D177: 34793 | E177: 安勤三 | F177: 7.2 | G177: 6.5 | H177: 3 | I177: 無擔保 | J177: 5 | K177: 5700 | L177: 100 | M177: 45300 | N177: 112 | O177: 121.5 | P177: 1.023 | Q177: 92.18 | R177: 108.5 | S177: 0.177 | T177: 109.53 | U177: 0.1882 | V177: 凱基證券 | W177: 電腦及週邊設備業 | X177: 616 | Y177: 25637 | Z177: 4.5 | AA177: 41.62 | AB177: 45296 | AC177: 570 | AD177: 45313 | AE177: 624292740 | AF177: 0.5 | AG177: 116.87 | AH177: 109.53
A178: 177 | B178: 45308 | C178: 4967 | D178: 49673 | E178: 十銓三 | F178: 7.2 | G178: 12 | H178: 3 | I178: 有擔保 | J178: 6 | K178: 10800 | L178: 102 | M178: 45306 | N178: 85.2 | O178: 81 | P178: 1.021 | Q178: 105.19 | R178: 114.16 | S178: 0.0853 | T178: 116.16 | U178: 0.1043 | V178: 永豐金證 | W178: 半導體業 | X178: 885 | Y178: 31244 | Z178: 2.89 | AA178: 35.3 | AB178: 45302 | AC178: 1080 | AD178: 45317 | AE178: 1254497820 | AF178: 0.5 | AG178: 121.19 | AH178: 116.16
A179: 178 | B179: 45308 | C179: 2476 | D179: 24762 | E179: 鉅祥二 | F179: 19.1 | G179: 10 | H179: 3 | I179: 無擔保 | J179: 4 | K179: 8500 | L179: 102 | M179: 45306 | N179: 73.6 | O179: 72.2 | P179: 1.02 | Q179: 101.94 | R179: 112.51 | S179: 0.1037 | T179: 113.8 | U179: 0.1164 | V179: 中信證券 | W179: 電子零組件業 | X179: 792 | Y179: 29362 | Z179: 3.45 | AA179: 37.07 | AB179: 45302 | AC179: 850 | AD179: 45317 | AE179: 967266980 | AF179: 0.5 | AG179: 121.1 | AH179: 113.8
A180: 179 | B180: 45343 | C180: 5263 | D180: 52635 | E180: 智崴五 | F180: 6.5 | G180: 8 | H180: 3 | I180: 有擔保 | J180: 7 | K180: 6800 | L180: 100 | M180: 45341 | N180: 115.5 | O180: 112 | P180: 1.023 | Q180: 103.13 | R180: 112.94 | S180: 0.0952 | T180: 114.83 | U180: 0.1135 | V180: 台新證券 | W180: 文化創意業 | X180: 692 | Y180: 28230 | Z180: 4.15 | AA180: 40.79 | AB180: 45337 | AC180: 680 | AD180: 45355 | AE180: 780836290 | AF180: 0.5 | AG180: 117 | AH180: 114.83
...

Sheet 05_CB競拍篩選條件區間
A1: 轉換價格 | B1: 股本大小 | C1: 規模大小 | D1: 信評 | E1: 產業分類 | F1: 發行年期 | G1: 發行券商 | H1: 承銷方式 | I1: 擔保 | J1: 資金用途
A2: 1_轉換價格_小於20元 | B2: 1_股本大小_小於3億 | C2: 1_發行規模_小於2億 | D2: 2 | E2: 資訊服務 | F2: 3 | G2: 統一證券 | H2: 詢圈 | I2: 有擔保 | J2: 償還銀行借款
A3: 2_轉換價格_介於20~50元 | B3: 2_股本大小_3~6億 | C3: 2_發行規模_2~5億 | D3: 3 | E3: 化工 | F3: 5 | G3: 第一金證 | H3: 競拍 | I3: 無擔保 | J3: 充實營運資金
A4: 3_轉換價格_介於50~100元 | B4: 3_股本大小_6~10億 | C4: 3_發行規模_5~10億 | D4: 4 | E4: 航運 | F4: 7 | G4: 國票證券 | J4: 併購/轉投資
A5: 4_轉換價格_介於100~150元 | B5: 4_股本大小_10~15億 | C5: 4_發行規模_10~15億 | D5: 5 | E5: 其他電子 | G5: 富邦證券 | J5: 購買機器設備
A6: 5_轉換價格_介於150~200元 | B6: 5_股本大小_15~20億 | C6: 5_發行規模_15~20億 | D6: 6 | E6: 油電燃氣 | G6: 永豐金證 | J6: 擴廠/建廠
A7: 6_轉換價格_大於200元 | B7: 6_股本大小_大於20億 | C7: 6_發行規模_大於20億 | D7: 7 | E7: 農業科技 | G7: 凱基證券 | J7: 購買不動產
D8: 8 | E8: 文化創意 | G8: 中信證券 | J8: 研發
D9: 9 | E9: 建材營造 | G9: 台新證券 | J9: 借新還舊
D10: BBB | E10: 生技醫療 | G10: 兆豐證券
E11: 電子零組件 | G11: 福邦證券
E12: 電腦及週邊設備 | G12: 群益證券
E13: 電機機械 | G13: 台中銀證
E14: 半導體 | G14: 元大證券
E15: 光電 | G15: 元富證券
E16: 運動休閒 | G16: 國泰證券
E17: 其他 | G17: 華南永昌
E18: 綠能環保 | G18: 合庫證券
E19: 電器電纜 | G19: 宏遠證券
E20: 通信網路 | G20: 康和證券
E21: 電子通路 | G21: 永豐證券
E22: 貿易百貨 | G22: 玉山證券
E23: 鋼鐵
E24: 觀光餐旅
E25: 金融保險
E26: 汽車
E27: 居家生活
E28: 數位雲端
E29: 造紙
E30: 塑膠
E31: 紡織纖維
E32: 食品
E33: 水泥

Sheet 06_發行案件
A1: 股票代號 | B1: 詢圈/競拍 | C1: 標的代號 | D1: 發行標的 | E1: TCRI/擔保 | F1: 發行量 | G1: 發行券商 | H1: 送件日 | I1: 生效日 | J1: 詢圈/投標期間 | K1: 溢價率 | L1: 轉換價 | M1: 掛牌日 | N1: 可拆解選擇權日 | O1: 承銷價格 | P1: 年期 | Q1: 賣回條件 | R1: 股本 | S1: 股價 | T1: 60天波動率 | U1: 備註
A2: =LEFT(C2,4) -> 3135 | B2: 詢圈 | C2: 31351 | D2: 凌航一 | E2: TCRI6 | F2: 10 | G2: 統一證券 | H2: 2025/10/31 | I2: 2025/11/18 | J2: 11/21-11/24 | K2: 1.0501 | L2: 52.19 | M2: 45995 | N2: 無報價2025/12/11 | O2: 100 | P2: 3Y | Q2: YTP(2)=(1%) | R2: 7.7493405 | S2: 67.3 | T2: 80.93
A3: =LEFT(C3,4) -> 2732 | B3: 詢圈 | C3: 27324 | D3: 六角四 | E3: TCRI5 | F3: 6 | G3: 華南永昌證 | H3: 2025/10/31 | I3: 2025/11/18 | J3: 11/24-11/26 | K3: 1.051 | L3: 74.3 | M3: 45999 | N3: 額度有限2025/12/15 | O3: 100 | P3: 5Y | Q3: YTP(2)=(0.5%) | R3: 4.651857 | S3: 74.9 | T3: 25.16
A4: =LEFT(C4,4) -> 6890 | B4: 競拍 | C4: 68902 | D4: 來億二KY | E4: TCRI5 | F4: 5 | G4: 富邦證券 | H4: 2025/10/23 | I4: 2025/11/11 | J4: 11/25-11/27 | K4: 1.02 | L4: 245.2 | M4: 46001 | N4: 無報價2025/12/17 | O4: 119.83 | P4: 3Y | Q4: YTM(3)=(0%) | R4: 24.94 | S4: 280.5 | T4: 53
A5: =LEFT(C5,4) -> 6442 | B5: 競拍 | C5: 64423 | D5: 光聖三 | E5: TCRI5 | F5: 15 | G5: 台新證券 | H5: 2025/10/21 | I5: 2025/11/07 | J5: 11/26-11/28 | K5: 1.02 | L5: 1065.9 | M5: 46002 | N5: 46009 | O5: 124.86 | P5: 3Y | Q5: YTP(2)=(0%) | R5: 7.7343078 | S5: 1190 | T5: 70.77
A6: =LEFT(C6,4) -> 5309 | B6: 詢圈 | C6: 53096 | D6: 系統電六 | E6: TCRI6 | F6: 7 | G6: 富邦證券 | H6: 2025/10/27 | I6: 2025/11/12 | J6: 11/28-12/2 | K6: 1.051 | L6: 63.5 | M6: 46003 | N6: 無報價2025/12/19 | O6: 100.5 | P6: 5Y | Q6: YTP(3)=(1%) | R6: 20.442378 | S6: 61.8 | T6: 56.65
A7: =LEFT(C7,4) -> 5309 | B7: 競拍 | C7: 53097 | D7: 系統電七 | E7: TCRI6 | F7: 5 | G7: 富邦證券 | H7: 2025/10/27 | I7: 2025/11/12 | J7: 11/28-12/2 | K7: 1.028 | L7: 55 | M7: 46006 | N7: 無報價2025/12/22 | O7: 116.91 | P7: 3Y | Q7: YTP(2)=(0.5%) | R7: 20.442378 | S7: 60.8 | T7: 56.65
A8: =LEFT(C8,4) -> 8042 | B8: 詢圈 | C8: 80426 | D8: 金山電六 | E8: TCRI7 | F8: 3.5 | G8: 永豐金證券 | H8: 2025/10/08 | I8: 2025/10/28 | J8: 12/3-12/4 | K8: 1.0526 | L8: 60 | M8: 46007 | N8: 無報價2025/12/23 | O8: 100 | P8: 3Y | Q8: YTP(2)=(0%) | R8: 12.946255 | S8: 57.3 | T8: 76.42
A9: =LEFT(C9,4) -> 4739 | B9: 競拍 | C9: 47394 | D9: 康普四 | E9: 第一銀行 | F9: 6 | G9: 福邦證券 | H9: 2025/11/03 | I9: 2025/11/19 | J9: 12/2-12/4 | K9: 1.086 | L9: 71 | M9: 46008 | N9: 46015 | O9: 110.46 | P9: 5Y | Q9: YTP(3)=(0%) | R9: 11.864927 | S9: 69.2 | T9: 38.92
A10: =LEFT(C10,4) -> 6796 | B10: 詢圈 | C10: 67962 | D10: 晉弘二 | E10: TCRI7 | F10: 2 | G10: 富邦證券 | H10: 2025/10/17 | I10: 2025/11/05 | J10: 12/8-12/10 | K10: 105.01-110% | L10: - | M10: 未定 | N10: 無報價 | O10: 100.5 | P10: 3Y | Q10: YTP(2)=(0-0.5%) | R10: 3.823397 | S10: 94.2 | T10: 31.96
A11: =LEFT(C11,4) -> 6904 | B11: 競拍 | C11: 69041 | D11: 伯鑫一 | E11: TCRI6 | F11: 2 | G11: 國泰證券 | H11: 2025/10/22 | I11: 2025/11/10 | J11: 12/10-12/12 | K11: 1.04 | L11: 130 | M11: 46017 | N11: 無報價2026/1/5 | O11: 102 | P11: 3Y | Q11: YTM(3)=(0%) | R11: 1.85 | S11: 118 | T11: 12.76
A12: =LEFT(C12,4) -> 3543 | B12: 競拍 | C12: 35431 | D12: 州巧一 | E12: 中國信託 | F12: 4 | G12: 福邦證券 | H12: 2025/10/27 | I12: 45988 | J12: 12/10-12/12 | K12: 1.048 | L12: 46.3 | M12: 46017 | N12: 46027 | O12: 100 | P12: 3Y | Q12: YTM(3)=(0%) | R12: 8.926315 | S12: 46.2 | T12: 67.83
A13: =LEFT(C13,4) -> 6670 | B13: 競拍 | C13: 66702 | D13: 復盛應用二 | E13: TCRI3 | F13: 15 | G13: 台新證券 | H13: 2025/06/18 | I13: 2025/07/04 | J13: 12/10-12/12 | K13: 1.0568 | L13: 270 | M13: 46017 | N13: 46027 | O13: 103 | P13: 3Y | Q13: YTM(3)=(0%) | R13: 13.938697 | S13: 257 | T13: 22.97 | U13: 延長三個月
A14: =LEFT(C14,4) -> 4113 | B14: 競拍 | C14: 41136 | D14: 聯上六 | E14: TCRI7 | F14: 3 | G14: 合庫證券 | H14: 2025/07/23 | I14: 45910 | J14: 未定 | K14: 102-110% | L14: - | M14: 未定 | N14: 未定 | O14: 100 | P14: 5Y | Q14: YTP(3)=(0.75%) | R14: 23.113814 | S14: 22.4 | T14: 31.76 | U14: 延長三個月
A15: =LEFT(C15,4) -> 2236 | B15: 詢圈 | C15: 22363 | D15: 百達三KY | E15: TCRI7 | F15: 4.5 | G15: 台新證券 | H15: 2025/08/07 | I15: 2025/08/25 | J15: 未定 | K15: 105.01-110% | L15: - | M15: 未定 | N15: 未定 | O15: 100 | P15: 5Y | Q15: YTP(3)=(0.5%) | R15: 5.9555656 | S15: 104.5 | T15: 43.12
A16: =LEFT(C16,4) -> 8299 | B16: 詢圈 | C16: 82993 | D16: 群聯三 | E16: TCRI3 | F16: 60 | G16: 凱基證券 | H16: 2025/08/08 | I16: 45910 | J16: 未定 | K16: 110-120% | L16: - | M16: 未定 | N16: 未定 | O16: 100-101 | P16: 5Y | Q16: YTP(3)=(0.6%) | R16: 20.662783 | S16: 1080 | T16: 77.95 | U16: 延長至115/3/9
A17: =LEFT(C17,4) -> 3715 | B17: 詢圈 | C17: 37151 | D17: 定穎一 | E17: TCRI5 | F17: 5 | G17: 凱基證券 | H17: 2025/11/03 | I17: 2025/11/19 | J17: 未定 | K17: 105.1-110% | L17: - | M17: 未定 | N17: 未定 | O17: 100.5-101 | P17: 3Y | Q17: YTM(3)=(0%) | R17: 27.767458 | S17: 112 | T17: 71.34
A18: =LEFT(C18,4) -> 3715 | B18: 競拍 | C18: 37152 | D18: 定穎二 | E18: TCRI5 | F18: 10 | G18: 凱基證券 | H18: 2025/11/03 | I18: 2025/11/19 | J18: 未定 | K18: 102-103% | L18: - | M18: 未定 | N18: 未定 | O18: 102 | P18: 3Y | Q18: YTM(3)=(0%) | R18: 27.767458 | S18: 112 | T18: 71.34
A19: =LEFT(C19,4) -> 6510 | B19: 競拍 | C19: 65101 | D19: 精測一 | E19: TCRI4 | F19: 20 | G19: 元大證券 | H19: 2025/11/07 | I19: 2025/11/25 | J19: 未定 | K19: 103-105% | L19: - | M19: 未定 | N19: 未定 | O19: 100-103 | P19: 3Y | Q19: YTM(3)=(0%) | R19: 3.2789022 | S19: 1900 | T19: 69.77
A20: =LEFT(C20,4) -> 2745 | B20: 競拍 | C20: 27451 | D20: 五福一 | E20: TCRI4 | F20: 3 | G20: 台新證券 | H20: 2025/11/18 | I20: 2025/12/04 | J20: 未定 | K20: 102-110% | L20: - | M20: 未定 | N20: 未定 | O20: 100 | P20: 3Y | Q20: YTP(2)=(0.5%) | R20: 3.3808526 | S20: 110 | T20: 27.49
A21: =LEFT(C21,4) -> 8431 | B21: 詢圈 | C21: 84312 | D21: 匯鑽科二 | E21: TCRI7 | F21: 3 | G21: 華南永昌證 | H21: 2025/11/27 | I21: 2025/12/15 | J21: 未定 | K21: 102-111% | L21: - | M21: 未定 | N21: 未定 | O21: 100 | P21: 3Y | Q21: YTP(2)=(0-0.5%) | R21: 4.4391482 | S21: 50.6 | T21: 39.63
A22: =LEFT(C22,4) -> 2467 | B22: 詢圈 | C22: 24672 | D22: 志聖二 | E22: TCRI5 | F22: 7 | G22: 富邦證券 | H22: 2025/11/28 | I22: 2025/12/16 | J22: 未定 | K22: 105.01-110% | L22: - | M22: 未定 | N22: 未定 | O22: 100-105 | P22: 3Y | Q22: YTP(2)=(0-0.5%) | R22: 15.675535 | S22: 206 | T22: 43.19
A23: =LEFT(C23,4) -> 2467 | B23: 競拍 | C23: 24673 | D23: 志聖三 | E23: TCRI5 | F23: 10 | G23: 富邦證券 | H23: 2025/11/28 | I23: 2025/12/16 | J23: 未定 | K23: 102-115% | L23: - | M23: 未定 | N23: 未定 | O23: 100 | P23: 3Y | Q23: YTP(2)=(0-0.5%) | R23: 15.675535 | S23: 206 | T23: 43.19
A24: =LEFT(C24,4) -> 3260 | B24: 詢圈 | C24: 32608 | D24: 威剛八 | E24: TCRI5 | F24: 20 | G24: 群益金鼎證 | H24: 2025/12/01 | I24: 2025/12/17 | J24: 未定 | K24: 101.5-110% | L24: - | M24: 未定 | N24: 未定 | O24: 100 | P24: 3Y | Q24: YTP(2)=(0-0.5%) | R24: 32.578565 | S24: 177 | T24: 59.31
A25: =LEFT(C25,4) -> 3717 | B25: 競拍 | C25: 37171 | D25: 聯嘉投控一 | E25: 安泰銀行 | F25: 7 | G25: 國泰證券 | H25: 2025/12/02 | I25: 2025/12/18 | J25: 未定 | K25: 102-105% | L25: - | M25: 未定 | N25: 未定 | O25: 100 | P25: 3Y | Q25: YTP(2)=(0.25%) | R25: 20.784544 | S25: 17.25 | T25: 27.77
A26: =LEFT(C26,4) -> 6199 | B26: 競拍 | C26: 61993 | D26: 天品三 | E26: 上海商銀 | F26: 2.5 | G26: 群益金鼎證 | H26: 2025/12/02 | I26: 2025/12/18 | J26: 未定 | K26: 102-110% | L26: - | M26: 未定 | N26: 未定 | O26: 100 | P26: 3Y | Q26: YTP(2)=(0-1%) | R26: 6.1760018 | S26: 95.9 | T26: 51.65
A27: =LEFT(C27,4) -> 6199 | B27: 詢圈 | C27: 61994 | D27: 天品四 | E27: TCRI7 | F27: 3.5 | G27: 群益金鼎證 | H27: 2025/12/02 | I27: 2025/12/18 | J27: 未定 | K27: 105.1-110% | L27: - | M27: 未定 | N27: 未定 | O27: 100-100.8 | P27: 3Y | Q27: YTP(2)=(0-1%) | R27: 6.1760018 | S27: 95.9 | T27: 51.65
A28: =LEFT(C28,4) -> 3290 | B28: 詢圈 | C28: 32904 | D28: 東浦四 | E28: TCRI6 | F28: 7 | G28: 台新證券 | H28: 2025/12/04 | I28: 2025/12/22 | J28: 未定 | K28: 101-110% | L28: - | M28: 未定 | N28: 未定 | O28: 100-100.5 | P28: 3Y | Q28: YTP(2)=(0.5%) | R28: 9.0215034 | S28: 42.25 | T28: 37.83
A29: =LEFT(C29,4) -> 3290 | B29: 競拍 | C29: 32905 | D29: 東浦五 | E29: TCRI6 | F29: 3 | G29: 台新證券 | H29: 2025/12/04 | I29: 2025/12/22 | J29: 未定 | K29: 101-110% | L29: - | M29: 未定 | N29: 未定 | O29: 100 | P29: 3Y | Q29: YTP(2)=(0.5%) | R29: 9.0215034 | S29: 42.25 | T29: 37.83
A30: =LEFT(C30,4) -> 4967 | B30: 競拍 | C30: 49674 | D30: 十銓四 | E30: 台中銀行 | F30: 20 | G30: 永豐金證券 | H30: 2025/12/04 | I30: 2025/12/22 | J30: 未定 | K30: 102-110% | L30: - | M30: 未定 | N30: 未定 | O30: 100 | P30: 3Y | Q30: YTM(3)=(0%) | R30: 8.4963288 | S30: 132.5 | T30: 69.04
A31: =LEFT(C31,4) -> 2301 | B31: 競拍 | C31: 23011 | D31: 光寶一 | E31: TCRI3 | F31: 40 | G31: 元大證券 | H31: 2025/12/05 | I31: 2025/12/23 | J31: 未定 | K31: 105-112% | L31: - | M31: 未定 | N31: 未定 | O31: 101 | P31: 5Y | Q31: YTP(3)=(0-0.25%) | R31: 231.67758 | S31: 160 | T31: 52.68
A32: =LEFT(C32,4) -> 2301 | B32: 詢圈 | C32: 23012 | D32: 光寶二 | E32: TCRI3 | F32: 80 | G32: 元大證券 | H32: 2025/12/05 | I32: 2025/12/23 | J32: 未定 | K32: 110-120% | L32: - | M32: 未定 | N32: 未定 | O32: 100 | P32: 5Y | Q32: YTP(3)=(0-0.25%) | R32: 231.67758 | S32: 160 | T32: 52.68
A33: =LEFT(C33,4) -> 3702 | B33: 詢圈 | C33: 370201 | D33: 大聯大E1 | E33: TCRI4 | F33: 30 | G33: 凱基證券 | H33: 2025/12/05 | I33: 2025/12/16 | J33: 未定 | K33: 102-130% | L33: - | M33: 未定 | N33: 未定 | O33: 100-101 | P33: 3Y | Q33: YTM(3)=(0%) | R33: 167.90568 | S33: 65.8 | T33: 27.37 | U33: 轉交換文曄
A34: =LEFT(C34,4) -> 8021 | B34: 競拍 | C34: 80212 | D34: 尖點二 | E34: TCRI4 | F34: 7 | G34: 福邦證券 | H34: 2025/12/05 | I34: 2025/12/23 | J34: 未定 | K34: 102-110% | L34: - | M34: 未定 | N34: 未定 | O34: 100 | P34: 5Y | Q34: YTP(3)=(0%) | R34: 14.204247 | S34: 135 | T34: 81.24
A35: =LEFT(C35,4) -> 6101 | B35: 競拍 | C35: 61011 | D35: 寬魚國際一 | E35: 有擔保 | F35: 1.5 | G35: 富邦證券 | H35: 2025/12/08 | I35: 2026/01/07 | J35: 未定 | K35: 102-105% | L35: - | M35: 未定 | N35: 未定 | O35: 100.5 | P35: 3Y | Q35: YTP(2)=(0%) | R35: 11.461837 | S35: 37.2 | T35: 10.27
A36: =LEFT(C36,4) -> 6101 | B36: 詢圈 | C36: 61012 | D36: 寬魚國際二 | E36: - | F36: 2.5 | G36: 富邦證券 | H36: 2025/12/08 | I36: 2026/01/07 | J36: 未定 | K36: 105.01-110% | L36: - | M36: 未定 | N36: 未定 | O36: 100 | P36: 3Y | Q36: YTP(2)=(0-0.5%) | R36: 11.461837 | S36: 37.2 | T36: 10.27
A37: =LEFT(C37,4) -> 8210 | B37: 詢圈 | C37: 82102 | D37: 勤誠二 | E37: TCRI4 | F37: 8 | G37: 元大證券 | H37: 2025/12/09 | I37: 2025/12/26 | J37: 未定 | K37: 105.1-108% | L37: - | M37: 未定 | N37: 未定 | O37: 100-102 | P37: 3Y | Q37: YTM(3)=(0%) | R37: 12.531915 | S37: 891 | T37: 53.58
A38: =LEFT(C38,4) -> 8210 | B38: 競拍 | C38: 82103 | D38: 勤誠三 | E38: TCRI4 | F38: 7 | G38: 元大證券 | H38: 2025/12/09 | I38: 2025/12/26 | J38: 未定 | K38: 102-108% | L38: - | M38: 未定 | N38: 未定 | O38: 102 | P38: 3Y | Q38: YTM(3)=(0%) | R38: 12.531915 | S38: 891 | T38: 53.58

Sheet 07_董事會決議
A1: 股鰾代號 | B1: 詢圈/競價 | C1: CB代碼 | D1: 發行標的 | E1: TCRI/擔保 | F1: 發行量 | G1: 主辦券商 | H1: 到期日 | I1: 董事會通過 | J1: 股本(億) | K1: 備註
A2: =LEFT(C2,4) -> 6807 | B2: 詢圈 | C2: 68071 | D2: 峰源一KY | E2: TCRI5 | F2: 6.5 | G2: 永豐金證券 | H2: 5Y | I2: 45729 | J2: 5.4
A3: =LEFT(C3,4) -> 6692 | B3: 詢圈 | C3: 66921 | D3: 進能服一 | E3: TCRI6 | F3: 2 | G3: 元大證券 | H3: 5Y | I3: 45785 | J3: 5.877639 | K3: 100-102%
A4: =LEFT(C4,4) -> 8431 | B4: 詢圈 | C4: 84312 | D4: 匯鑽科二 | E4: TCRI7 | F4: 5 | G4: 未定 | H4: 3Y | I4: 45786 | J4: 4.4391482
A5: =LEFT(C5,4) -> 2109 | B5: 詢圈 | C5: 21092 | D5: 華豐二 | E5: TCRI6 | F5: 10 | G5: 富邦證券 | H5: 3Y | I5: 45789 | J5: 27.934913
A6: =LEFT(C6,4) -> 4760 | B6: 詢圈 | C6: 47602 | D6: 勤凱二 | E6: TCRI6 | F6: 4 | G6: 未定 | H6: 3Y | I6: 45874 | J6: 3.2218283 | K6: 1.05
A7: =LEFT(C7,4) -> 6576 | B7: 競拍 | C7: 65761 | D7: 逸達一 | E7: 有擔保 | F7: 4 | G7: 未定 | H7: 3Y | I7: 45917 | J7: 15.741376
A8: =LEFT(C8,4) -> 6862 | B8: 詢圈 | C8: 68621 | D8: 三集瑞一KY | E8: TCRI6 | F8: 10 | G8: 華南永昌證 | H8: 3Y | I8: 45925 | J8: 5 | K8: 100-101%
A9: =LEFT(C9,4) -> 3701 | B9: 競拍 | C9: 37013 | D9: 大眾控三 | E9: TCRI6 | F9: 6 | G9: 富邦證券 | H9: 3Y | I9: 45933 | J9: 23.652661
A10: =LEFT(C10,4) -> 2329 | B10: 詢圈 | C10: 23291 | D10: 華泰一 | E10: TCRI5 | F10: 25 | G10: 未定 | H10: 3Y | I10: 45959 | J10: 65.900433 | K10: 100-102%
A11: =LEFT(C11,4) -> 2455 | B11: 詢圈 | C11: 24552 | D11: 全新二 | E11: TCRI5 | F11: 5 | G11: 未定 | H11: 3Y | I11: 45960 | J11: 18.490592 | K11: 100-110%
A12: =LEFT(C12,4) -> 2455 | B12: 競拍 | C12: 24553 | D12: 全新三 | E12: TCRI5 | F12: 25 | G12: 未定 | H12: 3Y | I12: 45960 | J12: 18.490592 | K12: 1.02
A13: =LEFT(C13,4) -> 2233 | B13: 詢圈 | C13: 22331 | D13: 宇隆一 | E13: TCRI4 | F13: 13 | G13: 未定 | H13: 3Y | I13: 45966 | J13: 6.0288089 | K13: 100-102%
A14: =LEFT(C14,4) -> 6547 | B14: 競拍 | C14: 65472 | D14: 高端二 | E14: 有擔保 | F14: 7.5 | G14: 未定 | H14: 3Y | I14: 45967 | J14: 32.874905 | K14: 1.005
A15: =LEFT(C15,4) -> 6672 | B15: 詢圈 | C15: 66721 | D15: 騰輝一KY | E15: TCRI6 | F15: 5 | G15: 永豐金證券 | H15: 5Y | I15: 45968 | J15: 7.1434745 | K15: 100-101%
A16: =LEFT(C16,4) -> 6672 | B16: 競拍 | C16: 66722 | D16: 騰輝二KY | E16: TCRI6 | F16: 5 | G16: 永豐金證券 | H16: 5Y | I16: 45968 | J16: 7.1434745
A17: =LEFT(C17,4) -> 3587 | B17: 競拍 | C17: 35872 | D17: 閎康二 | E17: TCRI4 | F17: 7 | G17: 元大證券 | H17: 5Y | I17: 45968 | J17: 6.7038234
A18: =LEFT(C18,4) -> 6913 | B18: 競拍 | C18: 69131 | D18: 鴻呈一 | E18: TCRI6 | F18: 4.5 | G18: 未定 | H18: 3Y | I18: 45971 | J18: 4.3848863
A19: =LEFT(C19,4) -> 5534 | B19: 詢圈 | C19: 55344 | D19: 長虹四 | E19: TCRI5 | F19: 15 | G19: 群益金鼎證 | H19: 5Y | I19: 45972 | J19: 29.032596 | K19: 100-101%
A20: =LEFT(C20,4) -> 6603 | B20: 詢圈 | C20: 66034 | D20: 富強鑫四 | E20: TCRI6 | F20: 4 | G20: 統一證券 | H20: 3Y | I20: 45972 | J20: 16.722059
A21: =LEFT(C21,4) -> 8476 | B21: 詢圈 | C21: 84762 | D21: 台境二 | E21: TCRI7 | F21: 2.5 | G21: 未定 | H21: 3Y | I21: 45973 | J21: 8.3113179 | K21: 100-101%
A22: =LEFT(C22,4) -> 2762 | B22: 詢圈 | C22: 27621 | D22: 世界健身一KY | E22: TCRI5 | F22: 5 | G22: 未定 | H22: 3Y | I22: 45973 | J22: 11.25 | K22: 100-101%
A23: =LEFT(C23,4) -> 8467 | B23: 競拍 | C23: 84674 | D23: 波力四KY | E23: 上海商銀 | F23: 2.1 | G23: 富邦證券 | H23: 3Y | I23: 45974 | J23: 5.0373575 | K23: 1.005
A24: =LEFT(C24,4) -> 8467 | B24: 詢圈 | C24: 84675 | D24: 波力五KY | E24: TCRI6 | F24: 3.9 | G24: 富邦證券 | H24: 3Y | I24: 45974 | J24: 5.0373575 | K24: 1.005
A25: =LEFT(C25,4) -> 3149 | B25: 競拍 | C25: 31494 | D25: 正達四 | E25: 有擔保 | F25: 6.5 | G25: 未定 | H25: 3Y | I25: 45983 | J25: 22.62336
A26: =LEFT(C26,4) -> 3011 | B26: 競拍 | C26: 30112 | D26: 今皓二 | E26: 有擔保 | F26: 4.5 | G26: 群益金鼎證 | H26: 3Y | I26: 45987 | J26: 11.271925
A27: =LEFT(C27,4) -> 4714 | B27: 競拍 | C27: 47148 | D27: 永捷八 | E27: 第一銀行 | F27: 3 | G27: 元富證券 | H27: 3Y | I27: 45996 | J27: 17.808819
A28: =LEFT(C28,4) -> 1727 | B28: 詢圈 | C28: 17272 | D28: 中華化二 | E28: TCRI6 | F28: 6 | G28: 富邦證券 | H28: 3Y | I28: 46001 | J28: 12.801956

Sheet 08_最新動態每週基本資料
